Workbook

Sheet Quoten
A1: Projektquoten Personal – Screw Drivers (G-18/25-1-P)
A3: Gelbe Zellen sind Eingabefelder. Die Quote gibt an, welcher Anteil der Personalkosten des Monats der geförderten Maßnahme zuzurechnen ist.
A4: Bezahlter Urlaub läuft anteilig mit und wird nicht gesondert herausgerechnet. Die Quoten müssen den tatsächlichen Projektbezug abbilden – sie sind subventionserheblich (§ 264 StGB).
A6: Monat | B6: Simon Blasen | C6: Marc Bendt | D6: F. D. Agustina | E6: Begründung / Beleg
A8: 2025-02 | B8: 1 | C8: 1 | E8: Vollzeit Screw Drivers
A9: 2025-03 | B9: 1 | C9: 1 | E9: Vollzeit Screw Drivers
A10: 2025-04 | B10: 1 | C10: 1 | E10: Vollzeit; Repo-Start 04/2025
A11: 2025-05 | B11: 1 | C11: 1 | E11: Gehalt SB reduziert; MB Austritt 31.05.
A12: 2025-06 | B12: 1 | E12: Gehalt SB 500 EUR
A13: 2025-07 | B13: 1 | E13: Gehalt SB 500 EUR
A14: 2025-08 | B14: 1 | E14: Gehalt SB 500 EUR
A15: 2025-09 | B15: 1 | E15: Gehalt SB 500 EUR; 1. Rate 23.09.
A16: 2025-10 | B16: 0.5 | C16: 1 | E16: 50 % SIMO; MB Wiedereintritt 01.10.
A17: 2025-11 | B17: 0.5 | C17: 1 | E17: 50 % SIMO
A18: 2025-12 | B18: 0.5 | C18: 1 | E18: 50 % SIMO
A19: 2026-01 | B19: 0.2 | C19: 1 | E19: 80 % SIMO; MB Austritt 31.01.
A20: 2026-02 | B20: 0.2 | E20: 80 % SIMO
A21: 2026-03 | B21: 0.95 | E21: 5 % weltenbauer (Kleinaufgaben)
A22: 2026-04 | B22: 0.95 | E22: 5 % weltenbauer (Kleinaufgaben)
A23: 2026-05 | B23: 0.95 | E23: 5 % weltenbauer
A24: 2026-06 | B24: 0.95 | D24: 1 | E24: Release-Vorbereitung
A25: 2026-07 | B25: 0.95 | D25: 1 | E25: Release-Vorbereitung
A26: 2026-08 | B26: 0.95 | D26: 1 | E26: Release 20.08.2026

Sheet Einzelkostenliste
A1: Einzelkostenliste – Screw Drivers, Projekt-Nr. G-18/25-1-P
A2: Creactstudios UG (haftungsbeschränkt) · Alle Beträge netto (vorsteuerabzugsberechtigt)
A4: Lfd. | B4: Kostenposition | C4: Empfänger | D4: Belegart | E4: Beleg-Nr. | F4: Belegdatum | G4: Leistungszeitraum | H4: Zahlungsdatum | I4: Betrag netto | J4: Quote | K4: anrechenbar | L4: BW | M4: Bemerkung
A5: A – PERSONALKOSTEN SIMON BLASEN (Geschäftsführer, sozialversicherungsfrei)
A6: 1 | B6: Programmierung / Projektmanagement | C6: Simon Blasen | D6: Gehaltsabrechnung | E6: LOGN 2025-02 | F6: 2025-02-Abrechnung | G6: 2025-02 | H6: 20.02.2025 | I6: 6000 | J6: =Quoten!B8 -> 1 | K6: =I6*J6 -> 6000 | L6: =K6 -> 6000 | M6: Brutto = Gesamtaufwand (SV-frei)
A7: 2 | B7: Programmierung / Projektmanagement | C7: Simon Blasen | D7: Gehaltsabrechnung | E7: LOGN 2025-03 | F7: 2025-03-Abrechnung | G7: 2025-03 | H7: 20.03.2025 | I7: 6000 | J7: =Quoten!B9 -> 1 | K7: =I7*J7 -> 6000 | L7: =K7 -> 6000 | M7: Brutto = Gesamtaufwand (SV-frei)
A8: 3 | B8: Programmierung / Projektmanagement | C8: Simon Blasen | D8: Gehaltsabrechnung | E8: LOGN 2025-04 | F8: 2025-04-Abrechnung | G8: 2025-04 | H8: 17.04.2025 | I8: 6000 | J8: =Quoten!B10 -> 1 | K8: =I8*J8 -> 6000 | L8: =K8 -> 6000 | M8: Brutto = Gesamtaufwand (SV-frei)
A9: 4 | B9: Programmierung / Projektmanagement | C9: Simon Blasen | D9: Gehaltsabrechnung | E9: LOGN 2025-05 | F9: 2025-05-Abrechnung | G9: 2025-05 | H9: 21.05.2025 | I9: 500 | J9: =Quoten!B11 -> 1 | K9: =I9*J9 -> 500 | L9: =K9 -> 500 | M9: Brutto = Gesamtaufwand (SV-frei)
A10: 5 | B10: Programmierung / Projektmanagement | C10: Simon Blasen | D10: Gehaltsabrechnung | E10: LOGN 2025-06 | F10: 2025-06-Abrechnung | G10: 2025-06 | H10: 24.06.2025 | I10: 500 | J10: =Quoten!B12 -> 1 | K10: =I10*J10 -> 500 | L10: =K10 -> 500 | M10: Brutto = Gesamtaufwand (SV-frei)
A11: 6 | B11: Programmierung / Projektmanagement | C11: Simon Blasen | D11: Gehaltsabrechnung | E11: LOGN 2025-07 | F11: 2025-07-Abrechnung | G11: 2025-07 | H11: 16.07.2025 | I11: 500 | J11: 1 | K11: =I11*J11 -> 500 | L11: =K11 -> 500 | M11: Brutto = Gesamtaufwand (SV-frei)
A12: 7 | B12: Programmierung / Projektmanagement | C12: Simon Blasen | D12: Gehaltsabrechnung | E12: LOGN 2025-08 | F12: 2025-08-Abrechnung | G12: 2025-08 | H12: 03.09.2025 | I12: 500 | J12: 1 | K12: =I12*J12 -> 500 | L12: =K12 -> 500 | M12: Brutto = Gesamtaufwand (SV-frei)
A13: 8 | B13: Programmierung / Projektmanagement | C13: Simon Blasen | D13: Gehaltsabrechnung | E13: LOGN 2025-09 | F13: 2025-09-Abrechnung | G13: 2025-09 | H13: 20.10.2025 | I13: 500 | J13: 0 | K13: =I13*J13 -> 0 | L13: =K13 -> 0 | M13: Brutto = Gesamtaufwand (SV-frei)
A14: 9 | B14: Programmierung / Projektmanagement | C14: Simon Blasen | D14: Gehaltsabrechnung | E14: LOGN 2025-10 | F14: 2025-10-Abrechnung | G14: 2025-10 | H14: 20.10.2025 | I14: 7500 | J14: 0.5 | K14: =I14*J14 -> 3750 | L14: =K14 -> 3750 | M14: Brutto = Gesamtaufwand (SV-frei)
A15: 10 | B15: Programmierung / Projektmanagement | C15: Simon Blasen | D15: Gehaltsabrechnung | E15: LOGN 2025-11 | F15: 2025-11-Abrechnung | G15: 2025-11 | H15: 20.11.2025 | I15: 7500 | J15: 0.5 | K15: =I15*J15 -> 3750 | L15: =K15 -> 3750 | M15: Brutto = Gesamtaufwand (SV-frei)
A16: 11 | B16: Programmierung / Projektmanagement | C16: Simon Blasen | D16: Gehaltsabrechnung | E16: LOGN 2025-12 | F16: 2025-12-Abrechnung | G16: 2025-12 | H16: 16.12.2025 | I16: 7500 | J16: 0.5 | K16: =I16*J16 -> 3750 | L16: =K16 -> 3750 | M16: Brutto = Gesamtaufwand (SV-frei)
A17: 12 | B17: Programmierung / Projektmanagement | C17: Simon Blasen | D17: Gehaltsabrechnung | E17: LOGN 2026-01 | F17: 2026-01-Abrechnung | G17: 2026-01 | H17: 20.01.2026 | I17: 7500 | J17: 0.5 | K17: =I17*J17 -> 3750 | L17: =K17 -> 3750 | M17: Brutto = Gesamtaufwand (SV-frei)
A18: 13 | B18: Programmierung / Projektmanagement | C18: Simon Blasen | D18: Gehaltsabrechnung | E18: LOGN 2026-02 | F18: 2026-02-Abrechnung | G18: 2026-02 | H18: 19.02.2026 | I18: 7500 | J18: 1 | K18: =I18*J18 -> 7500 | L18: =K18 -> 7500 | M18: Brutto = Gesamtaufwand (SV-frei)
A19: 14 | B19: Programmierung / Projektmanagement | C19: Simon Blasen | D19: Gehaltsabrechnung | E19: LOGN 2026-03 | F19: 2026-03-Abrechnung | G19: 2026-03 | H19: 23.03.2026 | I19: 7500 | J19: 0.95 | K19: =I19*J19 -> 7125 | L19: =K19 -> 7125 | M19: Brutto = Gesamtaufwand (SV-frei)
A20: 15 | B20: Programmierung / Projektmanagement | C20: Simon Blasen | D20: Gehaltsabrechnung | E20: LOGN 2026-04 | F20: 2026-04-Abrechnung | G20: 2026-04 | H20: 20.04.2026 | I20: 7500 | J20: 0.95 | K20: =I20*J20 -> 7125 | L20: =K20 -> 7125 | M20: Brutto = Gesamtaufwand (SV-frei)
A21: 16 | B21: Programmierung / Projektmanagement | C21: Simon Blasen | D21: Gehaltsabrechnung | E21: LOGN 2026-05 | F21: 2026-05-Abrechnung | G21: 2026-05 | H21: 23.05.2026 | I21: 4000 | J21: 1 | K21: =I21*J21 -> 4000 | L21: =K21 -> 4000 | M21: Brutto = Gesamtaufwand (SV-frei)
A22: 17 | B22: Programmierung / Projektmanagement | C22: Simon Blasen | D22: Gehaltsabrechnung | E22: LOGN 2026-06 | F22: 2026-06-Abrechnung | G22: 2026-06 | H22: 19.06.2026 | I22: 4000 | J22: 1 | K22: =I22*J22 -> 4000 | L22: =K22 -> 4000 | M22: Brutto = Gesamtaufwand (SV-frei)
... A24: 19 | B24: Programmierung / Projektmanagement | C24: Simon Blasen | D24: Gehaltsabrechnung | E24: LOGN 2026-08 | F24: 2026-08-Abrechnung | G24: 2026-08 | H24: 21.08.2026 | I24: 4000 | J24: 1 | K24: =I24*J24 -> 4000 | L24: =K24 -> 4000 | M24: Brutto = Gesamtaufwand (SV-frei)
A25: B – PERSONALKOSTEN MARC BENDT (Angestellter)
A26: 20 | B26: Art / Animation / Audio / Design | C26: Marc Bendt | D26: Gehaltsabrechnung | E26: LOGN 2025-02 | F26: 2025-02-Abrechnung | G26: 2025-02 | H26: 20.02.2025 | I26: 4308.83 | J26: =Quoten!C8 -> 1 | K26: =I26*J26 -> 4308.83 | L26: =K26 -> 4308.83 | M26: Brutto 3.504,00 + SV-AG 727.83 + Zus. AG 77.00
A27: 21 | B27: Art / Animation / Audio / Design | C27: Marc Bendt | D27: Gehaltsabrechnung | E27: LOGN 2025-03 | F27: 2025-03-Abrechnung | G27: 2025-03 | H27: 20.03.2025 | I27: 4308.83 | J27: =Quoten!C9 -> 1 | K27: =I27*J27 -> 4308.83 | L27: =K27 -> 4308.83 | M27: Brutto 3.504,00 + SV-AG 727.83 + Zus. AG 77.00
A28: 22 | B28: Art / Animation / Audio / Design | C28: Marc Bendt | D28: Gehaltsabrechnung | E28: LOGN 2025-04 | F28: 2025-04-Abrechnung | G28: 2025-04 | H28: 17.04.2025 | I28: 4308.83 | J28: =Quoten!C10 -> 1 | K28: =I28*J28 -> 4308.83 | L28: =K28 -> 4308.83 | M28: Brutto 3.504,00 + SV-AG 727.83 + Zus. AG 77.00
A29: 23 | B29: Art / Animation / Audio / Design | C29: Marc Bendt | D29: Gehaltsabrechnung | E29: LOGN 2025-05 | F29: 2025-05-Abrechnung | G29: 2025-05 | H29: 21.05.2025 | I29: 4308.83 | J29: =Quoten!C11 -> 1 | K29: =I29*J29 -> 4308.83 | L29: =K29 -> 4308.83 | M29: Brutto 3.504,00 + SV-AG 727.83 + Zus. AG 77.00
A30: 24 | B30: Art / Animation / Audio / Design | C30: Marc Bendt | D30: Gehaltsabrechnung | E30: LOGN 2025-10 | F30: 2025-10-Abrechnung | G30: 2025-10 | H30: 20.10.2025 | I30: 4308.83 | J30: 1 | K30: =I30*J30 -> 4308.83 | L30: =K30 -> 4308.83 | M30: Brutto 3.504,00 + SV-AG 727.83 + Zus. AG 77.00
A31: 25 | B31: Art / Animation / Audio / Design | C31: Marc Bendt | D31: Gehaltsabrechnung | E31: LOGN 2025-11 | F31: 2025-11-Abrechnung | G31: 2025-11 | H31: 20.11.2025 | I31: 4308.83 | J31: 1 | K31: =I31*J31 -> 4308.83 | L31: =K31 -> 4308.83 | M31: Brutto 3.504,00 + SV-AG 727.83 + Zus. AG 77.00
A32: 26 | B32: Art / Animation / Audio / Design | C32: Marc Bendt | D32: Gehaltsabrechnung | E32: LOGN 2025-12 | F32: 2025-12-Abrechnung | G32: 2025-12 | H32: 16.12.2025 | I32: 4308.83 | J32: 1 | K32: =I32*J32 -> 4308.83 | L32: =K32 -> 4308.83 | M32: Brutto 3.504,00 + SV-AG 727.83 + Zus. AG 77.00
A33: 27 | B33: Art / Animation / Audio / Design | C33: Marc Bendt | D33: Gehaltsabrechnung | E33: LOGN 2026-01 | F33: 2026-01-Abrechnung | G33: 2026-01 | H33: 20.01.2026 | I33: 4305.33 | J33: 1 | K33: =I33*J33 -> 4305.33 | L33: =K33 -> 4305.33 | M33: Brutto 3.504,00 + SV-AG 734.83 + Zus. AG 66.50
A34: C – PERSONALKOSTEN FRANSISKA DAMARA AGUSTINA (nur ansetzen nach Anzeige gem. AGB C.1)
A35: 28 | B35: Art / Animation / Audio / Design | C35: F. D. Agustina | D35: Gehaltsabrechnung | E35: LOGN 2026-06 | F35: 2026-06-Abrechnung | G35: 2026-06 | H35: — | I35: 0 | J35: =Quoten!D24 -> 1 | K35: =I35*J35 -> 0 | L35: =K35 -> 0 | M35: Gesamtaufwand aus Lohnjournal eintragen
A36: 29 | B36: Art / Animation / Audio / Design | C36: F. D. Agustina | D36: Gehaltsabrechnung | E36: LOGN 2026-07 | F36: 2026-07-Abrechnung | G36: 2026-07 | H36: 30.07.2026 | I36: 3000 | J36: =Quoten!D25 -> 1 | K36: =I36*J36 -> 3000 | L36: =K36 -> 3000 | M36: Gesamtaufwand aus Lohnjournal eintragen
A37: 30 | B37: Art / Animation / Audio / Design | C37: F. D. Agustina | D37: Gehaltsabrechnung | E37: LOGN 2026-08 | F37: 2026-08-Abrechnung | G37: 2026-08 | H37: 21.08.2026 | I37: 3000 | J37: =Quoten!D26 -> 1 | K37: =I37*J37 -> 3000 | L37: =K37 -> 3000 | M37: Gesamtaufwand aus Lohnjournal eintragen
A38: D – OUTSOURCING ART / ANIMATION (Lucas Mößner / Skybound 3D, Mannheim – Kleinunternehmer § 19 UStG)
A39: 31 | B39: Outsourcing Art / Animation | C39: Lucas Mößner (Skybound 3D) | D39: Rechnung | E39: SB000003 | F39: 28.01.2025 | G39: 01/2025 | H39: 28.01.2025 | I39: 1215 | J39: 0 | K39: =I39*J39 -> 0 | L39: =K39 -> 0 | M39: Vorentwicklung – vor Maßnahmebeginn, nicht ansetzbar
A40: 32 | B40: Outsourcing Art / Animation | C40: Lucas Mößner (Skybound 3D) | D40: Rechnung | E40: SB000004 | F40: 04.03.2025 | G40: 02/2025 | H40: 04.03.2025 | I40: 2415 | J40: 1 | K40: =I40*J40 -> 2415 | L40: =K40 -> 2415
A41: 33 | B41: Outsourcing Art / Animation | C41: Lucas Mößner (Skybound 3D) | D41: Rechnung | E41: SB000005 | F41: 01.04.2025 | G41: 03/2025 | H41: 01.04.2025 | I41: 2040 | J41: 1 | K41: =I41*J41 -> 2040 | L41: =K41 -> 2040
A42: 34 | B42: Outsourcing Art / Animation | C42: Lucas Mößner (Skybound 3D) | D42: Rechnung | E42: SB000006 | F42: 05.05.2025 | G42: 04/2025 | H42: 05.05.2025 | I42: 1440 | J42: 1 | K42: =I42*J42 -> 1440 | L42: =K42 -> 1440
...

Sheet Schlusskostenstand
A1: Schlusskostenstand – Screw Drivers, G-18/25-1-P
A2: Gliederung nach der genehmigten Vorkalkulation (Vertrag Ziff. 1)
A4: Funktionale Aufteilung der Personalkosten (gelb = Eingabe, Summe je Person muss 100 % ergeben)
B5: Programmierung | C5: Projektmanagement | D5: Art / Animation | E5: Audio | F5: Design | G5: Summe
A6: Simon Blasen | B6: 0.7 | C6: 0.15 | D6: 0.05 | E6: 0 | F6: 0.1 | G6: =SUM(B6:F6) -> 1
A7: Marc Bendt | B7: 0 | C7: 0 | D7: 0.3 | E7: 0.15 | F7: 0.55 | G7: =SUM(B7:F7) -> 1
A8: F. D. Agustina | B8: 0 | C8: 0 | D8: 0.5 | E8: 0 | F8: 0.5 | G8: =SUM(B8:F8) -> 1
A10: Anrechenbare Personalkosten je Person (aus Einzelkostenliste)
A11: Simon Blasen | B11: =SUMIF(Einzelkostenliste!$C$5:$C$54,"Simon Blasen",Einzelkostenliste!$K$5:$K$54) -> 72750
A12: Marc Bendt | B12: =SUMIF(Einzelkostenliste!$C$5:$C$54,"Marc Bendt",Einzelkostenliste!$K$5:$K$54) -> 34467.14
A13: F. D. Agustina | B13: =SUMIF(Einzelkostenliste!$C$5:$C$54,"F. D. Agustina",Einzelkostenliste!$K$5:$K$54) -> 6000
A16: Kostenposition | B16: Soll (Vertrag) | C16: Ist | D16: anerkennbar | E16: Abweichung | F16: in %
A17: (Freie) Mitarbeiter – Programmierung | B17: 50220 | C17: =$B$11*B$6+$B$12*B$7+$B$13*B$8 -> 50925 | D17: =MIN(B17,C17) -> 50220 | E17: =D17-B17 -> 0 | F17: =IFERROR(E17/B17,0) -> 0
A18: (Freie) Mitarbeiter – Art / Animation | B18: 12600 | C18: =$B$11*D$6+$B$12*D$7+$B$13*D$8 -> 16977.642 | D18: =MIN(B18,C18) -> 12600 | E18: =D18-B18 -> 0 | F18: =IFERROR(E18/B18,0) -> 0
A19: (Freie) Mitarbeiter – Audio | B19: 7560 | C19: =$B$11*E$6+$B$12*E$7+$B$13*E$8 -> 5170.071 | D19: =MIN(B19,C19) -> 5170.071 | E19: =D19-B19 -> -2389.929 | F19: =IFERROR(E19/B19,0) -> -0.31612817
A20: (Freie) Mitarbeiter – Design | B20: 25200 | C20: =$B$11*F$6+$B$12*F$7+$B$13*F$8 -> 29231.927 | D20: =MIN(B20,C20) -> 25200 | E20: =D20-B20 -> 0 | F20: =IFERROR(E20/B20,0) -> 0
A21: (Freie) Mitarbeiter – Projektmanagement | B21: 11880 | C21: =$B$11*C$6+$B$12*C$7+$B$13*C$8 -> 10912.5 | D21: =MIN(B21,C21) -> 10912.5 | E21: =D21-B21 -> -967.5 | F21: =IFERROR(E21/B21,0) -> -0.081439394
A22: Outsourcing – Art / Animation | B22: 21600 | C22: =SUMIF(Einzelkostenliste!$C$5:$C$54,"Lucas Mößner (Skybound 3D)",Einzelkostenliste!$K$5:$K$54) -> 21975 | D22: =MIN(B22,C22) -> 21600 | E22: =D22-B22 -> 0 | F22: =IFERROR(E22/B22,0) -> 0
A23: Fertigungskosten gesamt | B23: =SUM(B17:B22) -> 129060 | C23: =SUM(C17:C22) -> 135192.14 | D23: =SUM(D17:D22) -> 125702.57 | E23: =SUM(E17:E22) -> -3357.429 | F23: =IFERROR(E23/B23,0) -> -0.026014482
A25: Handlungskosten (Pauschale lt. Vertrag) | B25: 4391.1 | C25: 4391.1 | D25: =MIN(B25,C25,D23*0.075) -> 4391.1 | E25: =D25-B25 -> 0
A26: Prüfgebühr PwC | B26: 2032.25 | C26: 2032.25 | D26: 2032.25 | E26: =D26-B26 -> 0
A27: Nebenkosten gesamt | B27: =SUM(B25:B26) -> 6423.35 | C27: =SUM(C25:C26) -> 6423.35 | D27: =SUM(D25:D26) -> 6423.35 | E27: =SUM(E25:E26) -> 0
A29: GESAMTHERSTELLUNGSKOSTEN | B29: =B23+B27 -> 135483.35 | C29: =C23+C27 -> 141615.49 | D29: =D23+D27 -> 132125.92 | E29: =E23+E27 -> -3357.429 | F29: =IFERROR(E29/B29,0) -> -0.024781119
A31: Baden-Württemberg-Effekt (ohne Prüfgebühr) | B31: 133451.1 | D31: =D23+D25 -> 130093.67 | E31: =D31-B31 -> -3357.429
A32: Mindestbetrag lt. Vertrag Ziff. 3 f). Unterschreitung berechtigt zur Kürzung (AGB Ziff. 9 Abs. 3).

Sheet Schlussfinanzierung
A1: Schlussfinanzierung – Screw Drivers, G-18/25-1-P
A4: Finanzierungsbaustein | B4: Plan lt. Vertrag | C4: Ist | D4: Abweichung | E4: Bemerkung
A5: MFG Darlehen (Games BW, bedingt rückzahlbar) | B5: 67741.68 | C5: =MIN(67741.68,Schlusskostenstand!D29*0.5) -> 66062.961 | D5: =C5-B5 -> -1678.7195 | E5: 50 % der anerkannten Kosten
A6: Darlehen Headup GmbH | B6: 54666.64 | C6: 54666.66 | D6: =C6-B6 -> 0.02 | E6: 4 Zahlungen à 13.666,66 netto (SD030837–SD030840)
A7: Eigenmittel / Barmittel | B7: 13075.03 | C7: =Schlusskostenstand!D29-C5-C6 -> 11396.3 | D7: =C7-B7 -> -1678.7295 | E7: Restfinanzierung durch Eigenmittel
A8: Finanzierungsmittel insgesamt | B8: =SUM(B5:B7) -> 135483.35 | C8: =SUM(C5:C7) -> 132125.92 | D8: =SUM(D5:D7) -> -3357.429
A9: Kontrolle: Finanzierung ./. Gesamtkosten | C9: =C8-Schlusskostenstand!D29 -> 0 | E9: muss 0,00 ergeben
A12: Abrufstand MFG-Darlehen
A13: 1. Rate (50 %), bewilligt 23.09.2025 | B13: 33870.84 | C13: abzgl. Prüfgebühr 2.418,38 brutto einbehalten → 31.452,46 ausgezahlt
A14: 2. Rate (40 %), bewilligt 26.11.2025 | B14: 27096.67
A15: bereits abgerufen | B15: =SUM(B13:B14) -> 60967.51
A16: SCHLUSSRATE (Abrufformular) | B16: =C5-B15 -> 5095.4505 | C16: Negativer Betrag = Rückforderung
