Workbook

Sheet Übersicht
A1: Zeiterfassung – Übersicht Februar 2025 bis August 2026
A3: Einstellungen
A4: Soll-Arbeitszeit pro Arbeitstag (Std.) | B4: 8
A6: Legende
A7: Gelb hinterlegte Zellen mit blauer Schrift = Eingabefelder
A8: Weiße Zellen enthalten Formeln – bitte nicht überschreiben
A9: Monatsblätter: geleistete Stunden als Dezimalzahl in 'Ist-Std.' eintragen (Beispiel: 8,25 = 8 Std. 15 Min.)
A10: Spalte 'Art': leer = Arbeit, U = Urlaub, K = Krank, F = Feiertag, G = Gleittag
A11: Bei U / K / F / G wird automatisch die Soll-Zeit als Ist-Zeit gewertet – keine Eingabe nötig
A12: Gesetzliche Feiertage Baden-Württemberg sind in den Monatsblättern bereits mit 'F' eingetragen
A15: Monat | B15: Arbeitstage (Soll) | C15: Soll-Std. | D15: Ist-Std. | E15: Differenz | F15: Saldo kumuliert | G15: Urlaubstage | H15: Krankheitstage
A16: Februar 2025 | B16: ='Feb 2025'!$B$39 -> 20 | C16: ='Feb 2025'!$E$38 -> 160 | D16: ='Feb 2025'!$D$38 -> 160 | E16: ='Feb 2025'!$F$38 -> 0 | F16: =E16 -> 0 | G16: ='Feb 2025'!$B$40 -> 0 | H16: ='Feb 2025'!$B$41 -> 0
A17: März 2025 | B17: ='Mär 2025'!$B$39 -> 21 | C17: ='Mär 2025'!$E$38 -> 168 | D17: ='Mär 2025'!$D$38 -> 168 | E17: ='Mär 2025'!$F$38 -> 0 | F17: =F16+E17 -> 0 | G17: ='Mär 2025'!$B$40 -> 0 | H17: ='Mär 2025'!$B$41 -> 0
A18: April 2025 | B18: ='Apr 2025'!$B$39 -> 22 | C18: ='Apr 2025'!$E$38 -> 176 | D18: ='Apr 2025'!$D$38 -> 176 | E18: ='Apr 2025'!$F$38 -> 0 | F18: =F17+E18 -> 0 | G18: ='Apr 2025'!$B$40 -> 0 | H18: ='Apr 2025'!$B$41 -> 0
A19: Mai 2025 | B19: ='Mai 2025'!$B$39 -> 22 | C19: ='Mai 2025'!$E$38 -> 176 | D19: ='Mai 2025'!$D$38 -> 176 | E19: ='Mai 2025'!$F$38 -> 0 | F19: =F18+E19 -> 0 | G19: ='Mai 2025'!$B$40 -> 2 | H19: ='Mai 2025'!$B$41 -> 0
A20: Juni 2025 | B20: ='Jun 2025'!$B$39 -> 21 | C20: ='Jun 2025'!$E$38 -> 168 | D20: ='Jun 2025'!$D$38 -> 152 | E20: ='Jun 2025'!$F$38 -> -16 | F20: =F19+E20 -> -16 | G20: ='Jun 2025'!$B$40 -> 0 | H20: ='Jun 2025'!$B$41 -> 0
A21: Juli 2025 | B21: ='Jul 2025'!$B$39 -> 23 | C21: ='Jul 2025'!$E$38 -> 184 | D21: ='Jul 2025'!$D$38 -> 168 | E21: ='Jul 2025'!$F$38 -> 0 | F21: =F20+E21 -> -16 | G21: ='Jul 2025'!$B$40 -> 1 | H21: ='Jul 2025'!$B$41 -> 0
A22: August 2025 | B22: ='Aug 2025'!$B$39 -> 21 | C22: ='Aug 2025'!$E$38 -> 168 | D22: ='Aug 2025'!$D$38 -> 148 | E22: ='Aug 2025'!$F$38 -> -4 | F22: =F21+E22 -> -20 | G22: ='Aug 2025'!$B$40 -> 9 | H22: ='Aug 2025'!$B$41 -> 0
A23: September 2025 | B23: ='Sep 2025'!$B$39 -> 22 | C23: ='Sep 2025'!$E$38 -> 176 | D23: ='Sep 2025'!$D$38 -> 71 | E23: ='Sep 2025'!$F$38 -> -17 | F23: =F22+E23 -> -37 | G23: ='Sep 2025'!$B$40 -> 0 | H23: ='Sep 2025'!$B$41 -> 0
A24: Oktober 2025 | B24: ='Okt 2025'!$B$39 -> 23 | C24: ='Okt 2025'!$E$38 -> 184 | D24: ='Okt 2025'!$D$38 -> 66 | E24: ='Okt 2025'!$F$38 -> -6 | F24: =F23+E24 -> -43 | G24: ='Okt 2025'!$B$40 -> 0 | H24: ='Okt 2025'!$B$41 -> 0
A25: November 2025 | B25: ='Nov 2025'!$B$39 -> 20 | C25: ='Nov 2025'!$E$38 -> 160 | D25: ='Nov 2025'!$D$38 -> 28 | E25: ='Nov 2025'!$F$38 -> -4 | F25: =F24+E25 -> -47 | G25: ='Nov 2025'!$B$40 -> 2 | H25: ='Nov 2025'!$B$41 -> 0
A26: Dezember 2025 | B26: ='Dez 2025'!$B$39 -> 23 | C26: ='Dez 2025'!$E$38 -> 184 | D26: ='Dez 2025'!$D$38 -> 66 | E26: ='Dez 2025'!$F$38 -> -6 | F26: =F25+E26 -> -53 | G26: ='Dez 2025'!$B$40 -> 6 | H26: ='Dez 2025'!$B$41 -> 0
A27: Januar 2026 | B27: ='Jan 2026'!$B$39 -> 22 | C27: ='Jan 2026'!$E$38 -> 176 | D27: ='Jan 2026'!$D$38 -> 84 | E27: ='Jan 2026'!$F$38 -> -12 | F27: =F26+E27 -> -65 | G27: ='Jan 2026'!$B$40 -> 2 | H27: ='Jan 2026'!$B$41 -> 0
A28: Februar 2026 | B28: ='Feb 2026'!$B$39 -> 20 | C28: ='Feb 2026'!$E$38 -> 160 | D28: ='Feb 2026'!$D$38 -> 72 | E28: ='Feb 2026'!$F$38 -> -24 | F28: =F27+E28 -> -89 | G28: ='Feb 2026'!$B$40 -> 0 | H28: ='Feb 2026'!$B$41 -> 0
A29: März 2026 | B29: ='Mär 2026'!$B$39 -> 22 | C29: ='Mär 2026'!$E$38 -> 176 | D29: ='Mär 2026'!$D$38 -> 123 | E29: ='Mär 2026'!$F$38 -> -45 | F29: =F28+E29 -> -134 | G29: ='Mär 2026'!$B$40 -> 6 | H29: ='Mär 2026'!$B$41 -> 0
A30: April 2026 | B30: ='Apr 2026'!$B$39 -> 22 | C30: ='Apr 2026'!$E$38 -> 176 | D30: ='Apr 2026'!$D$38 -> 138 | E30: ='Apr 2026'!$F$38 -> -22 | F30: =F29+E30 -> -156 | G30: ='Apr 2026'!$B$40 -> 0 | H30: ='Apr 2026'!$B$41 -> 0
A31: Mai 2026 | B31: ='Mai 2026'!$B$39 -> 21 | C31: ='Mai 2026'!$E$38 -> 168 | D31: ='Mai 2026'!$D$38 -> 168 | E31: ='Mai 2026'!$F$38 -> 0 | F31: =F30+E31 -> -156 | G31: ='Mai 2026'!$B$40 -> 15 | H31: ='Mai 2026'!$B$41 -> 0
A32: Juni 2026 | B32: ='Jun 2026'!$B$39 -> 22 | C32: ='Jun 2026'!$E$38 -> 176 | D32: ='Jun 2026'!$D$38 -> 176 | E32: ='Jun 2026'!$F$38 -> 0 | F32: =F31+E32 -> -156 | G32: ='Jun 2026'!$B$40 -> 4 | H32: ='Jun 2026'!$B$41 -> 0
A33: Juli 2026 | B33: ='Jul 2026'!$B$39 -> 23 | C33: ='Jul 2026'!$E$38 -> 184 | D33: ='Jul 2026'!$D$38 -> 176 | E33: ='Jul 2026'!$F$38 -> 0 | F33: =F32+E33 -> -156 | G33: ='Jul 2026'!$B$40 -> 1 | H33: ='Jul 2026'!$B$41 -> 0
A34: August 2026 | B34: ='Aug 2026'!$B$39 -> 21 | C34: ='Aug 2026'!$E$38 -> 168 | D34: ='Aug 2026'!$D$38 -> 148 | E34: ='Aug 2026'!$F$38 -> -4 | F34: =F33+E34 -> -160 | G34: ='Aug 2026'!$B$40 -> 8 | H34: ='Aug 2026'!$B$41 -> 0
A35: Gesamt | B35: =SUM(B16:B34) -> 411 | C35: =SUM(C16:C34) -> 3288 | D35: =SUM(D16:D34) -> 2464 | E35: =SUM(E16:E34) -> -160 | F35: =F34 -> -160 | G35: =SUM(G16:G34) -> 56 | H35: =SUM(H16:H34) -> 0

Sheet Feb 2025
A1: Zeiterfassung Februar 2025
A2: Name: | B2: Simon Blasen
A3: Gelb = Eingabe · Ist-Std. als Dezimalzahl (8,25 = 8 Std. 15 Min.) · Art: U Urlaub, K Krank, F Feiertag, G Gleittag
A5: Datum | B5: Tag | C5: Art | D5: Ist-Std. | E5: Soll-Std. | F5: Differenz | G5: Bemerkung
A6: 45689 | B6: Sa | E6: =IF(WEEKDAY(A6,2)<=5,Übersicht!$B$4,0) -> 0 | F6: =IF(OR(C6="U",C6="K",C6="F",C6="G"),IF(D6="",0,D6),IF(D6="","",D6-E6))
A7: 45690 | B7: So | E7: =IF(WEEKDAY(A7,2)<=5,Übersicht!$B$4,0) -> 0 | F7: =IF(OR(C7="U",C7="K",C7="F",C7="G"),IF(D7="",0,D7),IF(D7="","",D7-E7))
A8: 45691 | B8: Mo | C8: SD | D8: 8 | E8: =IF(WEEKDAY(A8,2)<=5,Übersicht!$B$4,0) -> 8 | F8: =IF(OR(C8="U",C8="K",C8="F",C8="G"),IF(D8="",0,D8),IF(D8="","",D8-E8)) -> 0
A9: 45692 | B9: Di | C9: SD | D9: 8 | E9: =IF(WEEKDAY(A9,2)<=5,Übersicht!$B$4,0) -> 8 | F9: =IF(OR(C9="U",C9="K",C9="F",C9="G"),IF(D9="",0,D9),IF(D9="","",D9-E9)) -> 0
A10: 45693 | B10: Mi | C10: SD | D10: 8 | E10: =IF(WEEKDAY(A10,2)<=5,Übersicht!$B$4,0) -> 8 | F10: =IF(OR(C10="U",C10="K",C10="F",C10="G"),IF(D10="",0,D10),IF(D10="","",D10-E10)) -> 0
A11: 45694 | B11: Do | C11: SD | D11: 8 | E11: =IF(WEEKDAY(A11,2)<=5,Übersicht!$B$4,0) -> 8 | F11: =IF(OR(C11="U",C11="K",C11="F",C11="G"),IF(D11="",0,D11),IF(D11="","",D11-E11)) -> 0
A12: 45695 | B12: Fr | C12: SD | D12: 8 | E12: =IF(WEEKDAY(A12,2)<=5,Übersicht!$B$4,0) -> 8 | F12: =IF(OR(C12="U",C12="K",C12="F",C12="G"),IF(D12="",0,D12),IF(D12="","",D12-E12)) -> 0
A13: 45696 | B13: Sa | E13: =IF(WEEKDAY(A13,2)<=5,Übersicht!$B$4,0) -> 0 | F13: =IF(OR(C13="U",C13="K",C13="F",C13="G"),IF(D13="",0,D13),IF(D13="","",D13-E13))
A14: 45697 | B14: So | E14: =IF(WEEKDAY(A14,2)<=5,Übersicht!$B$4,0) -> 0 | F14: =IF(OR(C14="U",C14="K",C14="F",C14="G"),IF(D14="",0,D14),IF(D14="","",D14-E14))
A15: 45698 | B15: Mo | C15: SD | D15: 8 | E15: =IF(WEEKDAY(A15,2)<=5,Übersicht!$B$4,0) -> 8 | F15: =IF(OR(C15="U",C15="K",C15="F",C15="G"),IF(D15="",0,D15),IF(D15="","",D15-E15)) -> 0
A16: 45699 | B16: Di | C16: SD | D16: 8 | E16: =IF(WEEKDAY(A16,2)<=5,Übersicht!$B$4,0) -> 8 | F16: =IF(OR(C16="U",C16="K",C16="F",C16="G"),IF(D16="",0,D16),IF(D16="","",D16-E16)) -> 0
A17: 45700 | B17: Mi | C17: SD | D17: 8 | E17: =IF(WEEKDAY(A17,2)<=5,Übersicht!$B$4,0) -> 8 | F17: =IF(OR(C17="U",C17="K",C17="F",C17="G"),IF(D17="",0,D17),IF(D17="","",D17-E17)) -> 0
A18: 45701 | B18: Do | C18: SD | D18: 8 | E18: =IF(WEEKDAY(A18,2)<=5,Übersicht!$B$4,0) -> 8 | F18: =IF(OR(C18="U",C18="K",C18="F",C18="G"),IF(D18="",0,D18),IF(D18="","",D18-E18)) -> 0
A19: 45702 | B19: Fr | C19: SD | D19: 8 | E19: =IF(WEEKDAY(A19,2)<=5,Übersicht!$B$4,0) -> 8 | F19: =IF(OR(C19="U",C19="K",C19="F",C19="G"),IF(D19="",0,D19),IF(D19="","",D19-E19)) -> 0
A20: 45703 | B20: Sa | E20: =IF(WEEKDAY(A20,2)<=5,Übersicht!$B$4,0) -> 0 | F20: =IF(OR(C20="U",C20="K",C20="F",C20="G"),IF(D20="",0,D20),IF(D20="","",D20-E20))
A21: 45704 | B21: So | E21: =IF(WEEKDAY(A21,2)<=5,Übersicht!$B$4,0) -> 0 | F21: =IF(OR(C21="U",C21="K",C21="F",C21="G"),IF(D21="",0,D21),IF(D21="","",D21-E21))
A22: 45705 | B22: Mo | C22: SD | D22: 8 | E22: =IF(WEEKDAY(A22,2)<=5,Übersicht!$B$4,0) -> 8 | F22: =IF(OR(C22="U",C22="K",C22="F",C22="G"),IF(D22="",0,D22),IF(D22="","",D22-E22)) -> 0
A23: 45706 | B23: Di | C23: SD | D23: 8 | E23: =IF(WEEKDAY(A23,2)<=5,Übersicht!$B$4,0) -> 8 | F23: =IF(OR(C23="U",C23="K",C23="F",C23="G"),IF(D23="",0,D23),IF(D23="","",D23-E23)) -> 0
A24: 45707 | B24: Mi | C24: SD | D24: 8 | E24: =IF(WEEKDAY(A24,2)<=5,Übersicht!$B$4,0) -> 8 | F24: =IF(OR(C24="U",C24="K",C24="F",C24="G"),IF(D24="",0,D24),IF(D24="","",D24-E24)) -> 0
A25: 45708 | B25: Do | C25: SD | D25: 8 | E25: =IF(WEEKDAY(A25,2)<=5,Übersicht!$B$4,0) -> 8 | F25: =IF(OR(C25="U",C25="K",C25="F",C25="G"),IF(D25="",0,D25),IF(D25="","",D25-E25)) -> 0
A26: 45709 | B26: Fr | C26: SD | D26: 8 | E26: =IF(WEEKDAY(A26,2)<=5,Übersicht!$B$4,0) -> 8 | F26: =IF(OR(C26="U",C26="K",C26="F",C26="G"),IF(D26="",0,D26),IF(D26="","",D26-E26)) -> 0
A27: 45710 | B27: Sa | E27: =IF(WEEKDAY(A27,2)<=5,Übersicht!$B$4,0) -> 0 | F27: =IF(OR(C27="U",C27="K",C27="F",C27="G"),IF(D27="",0,D27),IF(D27="","",D27-E27))
A28: 45711 | B28: So | E28: =IF(WEEKDAY(A28,2)<=5,Übersicht!$B$4,0) -> 0 | F28: =IF(OR(C28="U",C28="K",C28="F",C28="G"),IF(D28="",0,D28),IF(D28="","",D28-E28))
A29: 45712 | B29: Mo | C29: SD | D29: 8 | E29: =IF(WEEKDAY(A29,2)<=5,Übersicht!$B$4,0) -> 8 | F29: =IF(OR(C29="U",C29="K",C29="F",C29="G"),IF(D29="",0,D29),IF(D29="","",D29-E29)) -> 0
A30: 45713 | B30: Di | C30: SD | D30: 8 | E30: =IF(WEEKDAY(A30,2)<=5,Übersicht!$B$4,0) -> 8 | F30: =IF(OR(C30="U",C30="K",C30="F",C30="G"),IF(D30="",0,D30),IF(D30="","",D30-E30)) -> 0
A31: 45714 | B31: Mi | C31: SD | D31: 8 | E31: =IF(WEEKDAY(A31,2)<=5,Übersicht!$B$4,0) -> 8 | F31: =IF(OR(C31="U",C31="K",C31="F",C31="G"),IF(D31="",0,D31),IF(D31="","",D31-E31)) -> 0
A32: 45715 | B32: Do | C32: SD | D32: 8 | E32: =IF(WEEKDAY(A32,2)<=5,Übersicht!$B$4,0) -> 8 | F32: =IF(OR(C32="U",C32="K",C32="F",C32="G"),IF(D32="",0,D32),IF(D32="","",D32-E32)) -> 0
A33: 45716 | B33: Fr | C33: SD | D33: 8 | E33: =IF(WEEKDAY(A33,2)<=5,Übersicht!$B$4,0) -> 8 | F33: =IF(OR(C33="U",C33="K",C33="F",C33="G"),IF(D33="",0,D33),IF(D33="","",D33-E33)) -> 0
A38: Summe | D38: =SUM(D6:D36)+SUMIF(C6:C36,"U",E6:E36)+SUMIF(C6:C36,"K",E6:E36)+SUMIF(C6:C36,"F",E6:E36)+SUMIF(C6:C36,"G",E6:E36) -> 160 | E38: =SUM(E6:E36) -> 160 | F38: =SUM(F6:F36) -> 0
A39: Arbeitstage (Soll) | B39: =COUNTIF(E6:E36,">0") -> 20
A40: Urlaubstage | B40: =COUNTIF(C6:C36,"U") -> 0
A41: Krankheitstage | B41: =COUNTIF(C6:C36,"K") -> 0
A42: Saldo kumuliert (Std.) | B42: =Übersicht!F16 -> 0

Sheet Mär 2025
A1: Zeiterfassung März 2025
A2: Name: | B2: Simon Blasen
A3: Gelb = Eingabe · Ist-Std. als Dezimalzahl (8,25 = 8 Std. 15 Min.) · Art: U Urlaub, K Krank, F Feiertag, G Gleittag
A5: Datum | B5: Tag | C5: Art | D5: Ist-Std. | E5: Soll-Std. | F5: Differenz | G5: Bemerkung
A6: 45717 | B6: Sa | E6: =IF(WEEKDAY(A6,2)<=5,Übersicht!$B$4,0) -> 0 | F6: =IF(OR(C6="U",C6="K",C6="F",C6="G"),IF(D6="",0,D6),IF(D6="","",D6-E6))
A7: 45718 | B7: So | E7: =IF(WEEKDAY(A7,2)<=5,Übersicht!$B$4,0) -> 0 | F7: =IF(OR(C7="U",C7="K",C7="F",C7="G"),IF(D7="",0,D7),IF(D7="","",D7-E7))
A8: 45719 | B8: Mo | C8: SD | D8: 8 | E8: =IF(WEEKDAY(A8,2)<=5,Übersicht!$B$4,0) -> 8 | F8: =IF(OR(C8="U",C8="K",C8="F",C8="G"),IF(D8="",0,D8),IF(D8="","",D8-E8)) -> 0
A9: 45720 | B9: Di | C9: SD | D9: 8 | E9: =IF(WEEKDAY(A9,2)<=5,Übersicht!$B$4,0) -> 8 | F9: =IF(OR(C9="U",C9="K",C9="F",C9="G"),IF(D9="",0,D9),IF(D9="","",D9-E9)) -> 0
A10: 45721 | B10: Mi | C10: SD | D10: 8 | E10: =IF(WEEKDAY(A10,2)<=5,Übersicht!$B$4,0) -> 8 | F10: =IF(OR(C10="U",C10="K",C10="F",C10="G"),IF(D10="",0,D10),IF(D10="","",D10-E10)) -> 0
A11: 45722 | B11: Do | C11: SD | D11: 8 | E11: =IF(WEEKDAY(A11,2)<=5,Übersicht!$B$4,0) -> 8 | F11: =IF(OR(C11="U",C11="K",C11="F",C11="G"),IF(D11="",0,D11),IF(D11="","",D11-E11)) -> 0
A12: 45723 | B12: Fr | C12: SD | D12: 8 | E12: =IF(WEEKDAY(A12,2)<=5,Übersicht!$B$4,0) -> 8 | F12: =IF(OR(C12="U",C12="K",C12="F",C12="G"),IF(D12="",0,D12),IF(D12="","",D12-E12)) -> 0
A13: 45724 | B13: Sa | E13: =IF(WEEKDAY(A13,2)<=5,Übersicht!$B$4,0) -> 0 | F13: =IF(OR(C13="U",C13="K",C13="F",C13="G"),IF(D13="",0,D13),IF(D13="","",D13-E13))
A14: 45725 | B14: So | E14: =IF(WEEKDAY(A14,2)<=5,Übersicht!$B$4,0) -> 0 | F14: =IF(OR(C14="U",C14="K",C14="F",C14="G"),IF(D14="",0,D14),IF(D14="","",D14-E14))
A15: 45726 | B15: Mo | C15: SD | D15: 8 | E15: =IF(WEEKDAY(A15,2)<=5,Übersicht!$B$4,0) -> 8 | F15: =IF(OR(C15="U",C15="K",C15="F",C15="G"),IF(D15="",0,D15),IF(D15="","",D15-E15)) -> 0
A16: 45727 | B16: Di | C16: SD | D16: 8 | E16: =IF(WEEKDAY(A16,2)<=5,Übersicht!$B$4,0) -> 8 | F16: =IF(OR(C16="U",C16="K",C16="F",C16="G"),IF(D16="",0,D16),IF(D16="","",D16-E16)) -> 0
A17: 45728 | B17: Mi | C17: SD | D17: 8 | E17: =IF(WEEKDAY(A17,2)<=5,Übersicht!$B$4,0) -> 8 | F17: =IF(OR(C17="U",C17="K",C17="F",C17="G"),IF(D17="",0,D17),IF(D17="","",D17-E17)) -> 0
A18: 45729 | B18: Do | C18: SD | D18: 8 | E18: =IF(WEEKDAY(A18,2)<=5,Übersicht!$B$4,0) -> 8 | F18: =IF(OR(C18="U",C18="K",C18="F",C18="G"),IF(D18="",0,D18),IF(D18="","",D18-E18)) -> 0
A19: 45730 | B19: Fr | C19: SD | D19: 8 | E19: =IF(WEEKDAY(A19,2)<=5,Übersicht!$B$4,0) -> 8 | F19: =IF(OR(C19="U",C19="K",C19="F",C19="G"),IF(D19="",0,D19),IF(D19="","",D19-E19)) -> 0
A20: 45731 | B20: Sa | E20: =IF(WEEKDAY(A20,2)<=5,Übersicht!$B$4,0) -> 0 | F20: =IF(OR(C20="U",C20="K",C20="F",C20="G"),IF(D20="",0,D20),IF(D20="","",D20-E20))
A21: 45732 | B21: So | E21: =IF(WEEKDAY(A21,2)<=5,Übersicht!$B$4,0) -> 0 | F21: =IF(OR(C21="U",C21="K",C21="F",C21="G"),IF(D21="",0,D21),IF(D21="","",D21-E21))
A22: 45733 | B22: Mo | C22: SD | D22: 8 | E22: =IF(WEEKDAY(A22,2)<=5,Übersicht!$B$4,0) -> 8 | F22: =IF(OR(C22="U",C22="K",C22="F",C22="G"),IF(D22="",0,D22),IF(D22="","",D22-E22)) -> 0
A23: 45734 | B23: Di | C23: SD | D23: 8 | E23: =IF(WEEKDAY(A23,2)<=5,Übersicht!$B$4,0) -> 8 | F23: =IF(OR(C23="U",C23="K",C23="F",C23="G"),IF(D23="",0,D23),IF(D23="","",D23-E23)) -> 0
A24: 45735 | B24: Mi | C24: SD | D24: 8 | E24: =IF(WEEKDAY(A24,2)<=5,Übersicht!$B$4,0) -> 8 | F24: =IF(OR(C24="U",C24="K",C24="F",C24="G"),IF(D24="",0,D24),IF(D24="","",D24-E24)) -> 0
A25: 45736 | B25: Do | C25: SD | D25: 8 | E25: =IF(WEEKDAY(A25,2)<=5,Übersicht!$B$4,0) -> 8 | F25: =IF(OR(C25="U",C25="K",C25="F",C25="G"),IF(D25="",0,D25),IF(D25="","",D25-E25)) -> 0
A26: 45737 | B26: Fr | C26: SD | D26: 8 | E26: =IF(WEEKDAY(A26,2)<=5,Übersicht!$B$4,0) -> 8 | F26: =IF(OR(C26="U",C26="K",C26="F",C26="G"),IF(D26="",0,D26),IF(D26="","",D26-E26)) -> 0
A27: 45738 | B27: Sa | E27: =IF(WEEKDAY(A27,2)<=5,Übersicht!$B$4,0) -> 0 | F27: =IF(OR(C27="U",C27="K",C27="F",C27="G"),IF(D27="",0,D27),IF(D27="","",D27-E27))
A28: 45739 | B28: So | E28: =IF(WEEKDAY(A28,2)<=5,Übersicht!$B$4,0) -> 0 | F28: =IF(OR(C28="U",C28="K",C28="F",C28="G"),IF(D28="",0,D28),IF(D28="","",D28-E28))
A29: 45740 | B29: Mo | C29: SD | D29: 8 | E29: =IF(WEEKDAY(A29,2)<=5,Übersicht!$B$4,0) -> 8 | F29: =IF(OR(C29="U",C29="K",C29="F",C29="G"),IF(D29="",0,D29),IF(D29="","",D29-E29)) -> 0
A30: 45741 | B30: Di | C30: SD | D30: 8 | E30: =IF(WEEKDAY(A30,2)<=5,Übersicht!$B$4,0) -> 8 | F30: =IF(OR(C30="U",C30="K",C30="F",C30="G"),IF(D30="",0,D30),IF(D30="","",D30-E30)) -> 0
A31: 45742 | B31: Mi | C31: SD | D31: 8 | E31: =IF(WEEKDAY(A31,2)<=5,Übersicht!$B$4,0) -> 8 | F31: =IF(OR(C31="U",C31="K",C31="F",C31="G"),IF(D31="",0,D31),IF(D31="","",D31-E31)) -> 0
A32: 45743 | B32: Do | C32: SD | D32: 8 | E32: =IF(WEEKDAY(A32,2)<=5,Übersicht!$B$4,0) -> 8 | F32: =IF(OR(C32="U",C32="K",C32="F",C32="G"),IF(D32="",0,D32),IF(D32="","",D32-E32)) -> 0
A33: 45744 | B33: Fr | C33: SD | D33: 8 | E33: =IF(WEEKDAY(A33,2)<=5,Übersicht!$B$4,0) -> 8 | F33: =IF(OR(C33="U",C33="K",C33="F",C33="G"),IF(D33="",0,D33),IF(D33="","",D33-E33)) -> 0
A34: 45745 | B34: Sa | E34: =IF(WEEKDAY(A34,2)<=5,Übersicht!$B$4,0) -> 0 | F34: =IF(OR(C34="U",C34="K",C34="F",C34="G"),IF(D34="",0,D34),IF(D34="","",D34-E34))
A35: 45746 | B35: So | E35: =IF(WEEKDAY(A35,2)<=5,Übersicht!$B$4,0) -> 0 | F35: =IF(OR(C35="U",C35="K",C35="F",C35="G"),IF(D35="",0,D35),IF(D35="","",D35-E35))
A36: 45747 | B36: Mo | C36: SD | D36: 8 | E36: =IF(WEEKDAY(A36,2)<=5,Übersicht!$B$4,0) -> 8 | F36: =IF(OR(C36="U",C36="K",C36="F",C36="G"),IF(D36="",0,D36),IF(D36="","",D36-E36)) -> 0
A38: Summe | D38: =SUM(D6:D36)+SUMIF(C6:C36,"U",E6:E36)+SUMIF(C6:C36,"K",E6:E36)+SUMIF(C6:C36,"F",E6:E36)+SUMIF(C6:C36,"G",E6:E36) -> 168 | E38: =SUM(E6:E36) -> 168 | F38: =SUM(F6:F36) -> 0
A39: Arbeitstage (Soll) | B39: =COUNTIF(E6:E36,">0") -> 21
A40: Urlaubstage | B40: =COUNTIF(C6:C36,"U") -> 0
A41: Krankheitstage | B41: =COUNTIF(C6:C36,"K") -> 0
A42: Saldo kumuliert (Std.) | B42: =Übersicht!F17 -> 0

Sheet Apr 2025
A1: Zeiterfassung April 2025
A2: Name: | B2: Simon Blasen
A3: Gelb = Eingabe · Ist-Std. als Dezimalzahl (8,25 = 8 Std. 15 Min.) · Art: U Urlaub, K Krank, F Feiertag, G Gleittag
A5: Datum | B5: Tag | C5: Art | D5: Ist-Std. | E5: Soll-Std. | F5: Differenz | G5: Bemerkung
A6: 45748 | B6: Di | C6: SD | D6: 8 | E6: =IF(WEEKDAY(A6,2)<=5,Übersicht!$B$4,0) -> 8 | F6: =IF(OR(C6="U",C6="K",C6="F",C6="G"),IF(D6="",0,D6),IF(D6="","",D6-E6)) -> 0
A7: 45749 | B7: Mi | C7: SD | D7: 8 | E7: =IF(WEEKDAY(A7,2)<=5,Übersicht!$B$4,0) -> 8 | F7: =IF(OR(C7="U",C7="K",C7="F",C7="G"),IF(D7="",0,D7),IF(D7="","",D7-E7)) -> 0
A8: 45750 | B8: Do | C8: SD | D8: 8 | E8: =IF(WEEKDAY(A8,2)<=5,Übersicht!$B$4,0) -> 8 | F8: =IF(OR(C8="U",C8="K",C8="F",C8="G"),IF(D8="",0,D8),IF(D8="","",D8-E8)) -> 0
A9: 45751 | B9: Fr | C9: SD | D9: 8 | E9: =IF(WEEKDAY(A9,2)<=5,Übersicht!$B$4,0) -> 8 | F9: =IF(OR(C9="U",C9="K",C9="F",C9="G"),IF(D9="",0,D9),IF(D9="","",D9-E9)) -> 0
A10: 45752 | B10: Sa | E10: =IF(WEEKDAY(A10,2)<=5,Übersicht!$B$4,0) -> 0 | F10: =IF(OR(C10="U",C10="K",C10="F",C10="G"),IF(D10="",0,D10),IF(D10="","",D10-E10))
A11: 45753 | B11: So | E11: =IF(WEEKDAY(A11,2)<=5,Übersicht!$B$4,0) -> 0 | F11: =IF(OR(C11="U",C11="K",C11="F",C11="G"),IF(D11="",0,D11),IF(D11="","",D11-E11))
A12: 45754 | B12: Mo | C12: SD | D12: 8 | E12: =IF(WEEKDAY(A12,2)<=5,Übersicht!$B$4,0) -> 8 | F12: =IF(OR(C12="U",C12="K",C12="F",C12="G"),IF(D12="",0,D12),IF(D12="","",D12-E12)) -> 0
A13: 45755 | B13: Di | C13: SD | D13: 8 | E13: =IF(WEEKDAY(A13,2)<=5,Übersicht!$B$4,0) -> 8 | F13: =IF(OR(C13="U",C13="K",C13="F",C13="G"),IF(D13="",0,D13),IF(D13="","",D13-E13)) -> 0
A14: 45756 | B14: Mi | C14: SD | D14: 8 | E14: =IF(WEEKDAY(A14,2)<=5,Übersicht!$B$4,0) -> 8 | F14: =IF(OR(C14="U",C14="K",C14="F",C14="G"),IF(D14="",0,D14),IF(D14="","",D14-E14)) -> 0
A15: 45757 | B15: Do | C15: SD | D15: 8 | E15: =IF(WEEKDAY(A15,2)<=5,Übersicht!$B$4,0) -> 8 | F15: =IF(OR(C15="U",C15="K",C15="F",C15="G"),IF(D15="",0,D15),IF(D15="","",D15-E15)) -> 0
A16: 45758 | B16: Fr | C16: SD | D16: 8 | E16: =IF(WEEKDAY(A16,2)<=5,Übersicht!$B$4,0) -> 8 | F16: =IF(OR(C16="U",C16="K",C16="F",C16="G"),IF(D16="",0,D16),IF(D16="","",D16-E16)) -> 0
A17: 45759 | B17: Sa | E17: =IF(WEEKDAY(A17,2)<=5,Übersicht!$B$4,0) -> 0 | F17: =IF(OR(C17="U",C17="K",C17="F",C17="G"),IF(D17="",0,D17),IF(D17="","",D17-E17))
A18: 45760 | B18: So | E18: =IF(WEEKDAY(A18,2)<=5,Übersicht!$B$4,0) -> 0 | F18: =IF(OR(C18="U",C18="K",C18="F",C18="G"),IF(D18="",0,D18),IF(D18="","",D18-E18))
A19: 45761 | B19: Mo | C19: SD | D19: 8 | E19: =IF(WEEKDAY(A19,2)<=5,Übersicht!$B$4,0) -> 8 | F19: =IF(OR(C19="U",C19="K",C19="F",C19="G"),IF(D19="",0,D19),IF(D19="","",D19-E19)) -> 0
A20: 45762 | B20: Di | C20: SD | D20: 8 | E20: =IF(WEEKDAY(A20,2)<=5,Übersicht!$B$4,0) -> 8 | F20: =IF(OR(C20="U",C20="K",C20="F",C20="G"),IF(D20="",0,D20),IF(D20="","",D20-E20)) -> 0
A21: 45763 | B21: Mi | C21: SD | D21: 8 | E21: =IF(WEEKDAY(A21,2)<=5,Übersicht!$B$4,0) -> 8 | F21: =IF(OR(C21="U",C21="K",C21="F",C21="G"),IF(D21="",0,D21),IF(D21="","",D21-E21)) -> 0
A22: 45764 | B22: Do | C22: SD | D22: 8 | E22: =IF(WEEKDAY(A22,2)<=5,Übersicht!$B$4,0) -> 8 | F22: =IF(OR(C22="U",C22="K",C22="F",C22="G"),IF(D22="",0,D22),IF(D22="","",D22-E22)) -> 0
A23: 45765 | B23: Fr | C23: F | E23: =IF(WEEKDAY(A23,2)<=5,Übersicht!$B$4,0) -> 8 | F23: =IF(OR(C23="U",C23="K",C23="F",C23="G"),IF(D23="",0,D23),IF(D23="","",D23-E23)) -> 0 | G23: Feiertag BW: Karfreitag
A24: 45766 | B24: Sa | E24: =IF(WEEKDAY(A24,2)<=5,Übersicht!$B$4,0) -> 0 | F24: =IF(OR(C24="U",C24="K",C24="F",C24="G"),IF(D24="",0,D24),IF(D24="","",D24-E24))
A25: 45767 | B25: So | E25: =IF(WEEKDAY(A25,2)<=5,Übersicht!$B$4,0) -> 0 | F25: =IF(OR(C25="U",C25="K",C25="F",C25="G"),IF(D25="",0,D25),IF(D25="","",D25-E25))
A26: 45768 | B26: Mo | C26: F | E26: =IF(WEEKDAY(A26,2)<=5,Übersicht!$B$4,0) -> 8 | F26: =IF(OR(C26="U",C26="K",C26="F",C26="G"),IF(D26="",0,D26),IF(D26="","",D26-E26)) -> 0 | G26: Feiertag BW: Ostermontag
A27: 45769 | B27: Di | C27: SD | D27: 8 | E27: =IF(WEEKDAY(A27,2)<=5,Übersicht!$B$4,0) -> 8 | F27: =IF(OR(C27="U",C27="K",C27="F",C27="G"),IF(D27="",0,D27),IF(D27="","",D27-E27)) -> 0
A28: 45770 | B28: Mi | C28: SD | D28: 8 | E28: =IF(WEEKDAY(A28,2)<=5,Übersicht!$B$4,0) -> 8 | F28: =IF(OR(C28="U",C28="K",C28="F",C28="G"),IF(D28="",0,D28),IF(D28="","",D28-E28)) -> 0
A29: 45771 | B29: Do | C29: SD | D29: 8 | E29: =IF(WEEKDAY(A29,2)<=5,Übersicht!$B$4,0) -> 8 | F29: =IF(OR(C29="U",C29="K",C29="F",C29="G"),IF(D29="",0,D29),IF(D29="","",D29-E29)) -> 0
A30: 45772 | B30: Fr | C30: SD | D30: 8 | E30: =IF(WEEKDAY(A30,2)<=5,Übersicht!$B$4,0) -> 8 | F30: =IF(OR(C30="U",C30="K",C30="F",C30="G"),IF(D30="",0,D30),IF(D30="","",D30-E30)) -> 0
A31: 45773 | B31: Sa | E31: =IF(WEEKDAY(A31,2)<=5,Übersicht!$B$4,0) -> 0 | F31: =IF(OR(C31="U",C31="K",C31="F",C31="G"),IF(D31="",0,D31),IF(D31="","",D31-E31))
A32: 45774 | B32: So | E32: =IF(WEEKDAY(A32,2)<=5,Übersicht!$B$4,0) -> 0 | F32: =IF(OR(C32="U",C32="K",C32="F",C32="G"),IF(D32="",0,D32),IF(D32="","",D32-E32))
A33: 45775 | B33: Mo | C33: SD | D33: 8 | E33: =IF(WEEKDAY(A33,2)<=5,Übersicht!$B$4,0) -> 8 | F33: =IF(OR(C33="U",C33="K",C33="F",C33="G"),IF(D33="",0,D33),IF(D33="","",D33-E33)) -> 0
A34: 45776 | B34: Di | C34: SD | D34: 8 | E34: =IF(WEEKDAY(A34,2)<=5,Übersicht!$B$4,0) -> 8 | F34: =IF(OR(C34="U",C34="K",C34="F",C34="G"),IF(D34="",0,D34),IF(D34="","",D34-E34)) -> 0
A35: 45777 | B35: Mi | C35: SD | D35: 8 | E35: =IF(WEEKDAY(A35,2)<=5,Übersicht!$B$4,0) -> 8 | F35: =IF(OR(C35="U",C35="K",C35="F",C35="G"),IF(D35="",0,D35),IF(D35="","",D35-E35)) -> 0
A38: Summe | D38: =SUM(D6:D36)+SUMIF(C6:C36,"U",E6:E36)+SUMIF(C6:C36,"K",E6:E36)+SUMIF(C6:C36,"F",E6:E36)+SUMIF(C6:C36,"G",E6:E36) -> 176 | E38: =SUM(E6:E36) -> 176 | F38: =SUM(F6:F36) -> 0
A39: Arbeitstage (Soll) | B39: =COUNTIF(E6:E36,">0") -> 22
A40: Urlaubstage | B40: =COUNTIF(C6:C36,"U") -> 0
A41: Krankheitstage | B41: =COUNTIF(C6:C36,"K") -> 0
A42: Saldo kumuliert (Std.) | B42: =Übersicht!F18 -> 0

Sheet Mai 2025
A1: Zeiterfassung Mai 2025
A2: Name:
A3: Gelb = Eingabe · Ist-Std. als Dezimalzahl (8,25 = 8 Std. 15 Min.) · Art: U Urlaub, K Krank, F Feiertag, G Gleittag
A5: Datum | B5: Tag | C5: Art | D5: Ist-Std. | E5: Soll-Std. | F5: Differenz | G5: Bemerkung
A6: 45778 | B6: Do | C6: F | E6: =IF(WEEKDAY(A6,2)<=5,Übersicht!$B$4,0) -> 8 | F6: =IF(OR(C6="U",C6="K",C6="F",C6="G"),IF(D6="",0,D6),IF(D6="","",D6-E6)) -> 0 | G6: Feiertag BW: Tag der Arbeit
A7: 45779 | B7: Fr | C7: SD | D7: 8 | E7: =IF(WEEKDAY(A7,2)<=5,Übersicht!$B$4,0) -> 8 | F7: =IF(OR(C7="U",C7="K",C7="F",C7="G"),IF(D7="",0,D7),IF(D7="","",D7-E7)) -> 0
A8: 45780 | B8: Sa | E8: =IF(WEEKDAY(A8,2)<=5,Übersicht!$B$4,0) -> 0 | F8: =IF(OR(C8="U",C8="K",C8="F",C8="G"),IF(D8="",0,D8),IF(D8="","",D8-E8))
A9: 45781 | B9: So | E9: =IF(WEEKDAY(A9,2)<=5,Übersicht!$B$4,0) -> 0 | F9: =IF(OR(C9="U",C9="K",C9="F",C9="G"),IF(D9="",0,D9),IF(D9="","",D9-E9))
A10: 45782 | B10: Mo | C10: SD | D10: 8 | E10: =IF(WEEKDAY(A10,2)<=5,Übersicht!$B$4,0) -> 8 | F10: =IF(OR(C10="U",C10="K",C10="F",C10="G"),IF(D10="",0,D10),IF(D10="","",D10-E10)) -> 0
A11: 45783 | B11: Di | C11: SD | D11: 8 | E11: =IF(WEEKDAY(A11,2)<=5,Übersicht!$B$4,0) -> 8 | F11: =IF(OR(C11="U",C11="K",C11="F",C11="G"),IF(D11="",0,D11),IF(D11="","",D11-E11)) -> 0
A12: 45784 | B12: Mi | C12: SD | D12: 8 | E12: =IF(WEEKDAY(A12,2)<=5,Übersicht!$B$4,0) -> 8 | F12: =IF(OR(C12="U",C12="K",C12="F",C12="G"),IF(D12="",0,D12),IF(D12="","",D12-E12)) -> 0
A13: 45785 | B13: Do | C13: SD | D13: 8 | E13: =IF(WEEKDAY(A13,2)<=5,Übersicht!$B$4,0) -> 8 | F13: =IF(OR(C13="U",C13="K",C13="F",C13="G"),IF(D13="",0,D13),IF(D13="","",D13-E13)) -> 0
A14: 45786 | B14: Fr | C14: SD | D14: 8 | E14: =IF(WEEKDAY(A14,2)<=5,Übersicht!$B$4,0) -> 8 | F14: =IF(OR(C14="U",C14="K",C14="F",C14="G"),IF(D14="",0,D14),IF(D14="","",D14-E14)) -> 0
A15: 45787 | B15: Sa | E15: =IF(WEEKDAY(A15,2)<=5,Übersicht!$B$4,0) -> 0 | F15: =IF(OR(C15="U",C15="K",C15="F",C15="G"),IF(D15="",0,D15),IF(D15="","",D15-E15))
A16: 45788 | B16: So | E16: =IF(WEEKDAY(A16,2)<=5,Übersicht!$B$4,0) -> 0 | F16: =IF(OR(C16="U",C16="K",C16="F",C16="G"),IF(D16="",0,D16),IF(D16="","",D16-E16))
A17: 45789 | B17: Mo | C17: SD | D17: 8 | E17: =IF(WEEKDAY(A17,2)<=5,Übersicht!$B$4,0) -> 8 | F17: =IF(OR(C17="U",C17="K",C17="F",C17="G"),IF(D17="",0,D17),IF(D17="","",D17-E17)) -> 0
A18: 45790 | B18: Di | C18: SD | D18: 8 | E18: =IF(WEEKDAY(A18,2)<=5,Übersicht!$B$4,0) -> 8 | F18: =IF(OR(C18="U",C18="K",C18="F",C18="G"),IF(D18="",0,D18),IF(D18="","",D18-E18)) -> 0
A19: 45791 | B19: Mi | C19: U | E19: =IF(WEEKDAY(A19,2)<=5,Übersicht!$B$4,0) -> 8 | F19: =IF(OR(C19="U",C19="K",C19="F",C19="G"),IF(D19="",0,D19),IF(D19="","",D19-E19)) -> 0
A20: 45792 | B20: Do | C20: SD | D20: 8 | E20: =IF(WEEKDAY(A20,2)<=5,Übersicht!$B$4,0) -> 8 | F20: =IF(OR(C20="U",C20="K",C20="F",C20="G"),IF(D20="",0,D20),IF(D20="","",D20-E20)) -> 0
A21: 45793 | B21: Fr | C21: SD | D21: 8 | E21: =IF(WEEKDAY(A21,2)<=5,Übersicht!$B$4,0) -> 8 | F21: =IF(OR(C21="U",C21="K",C21="F",C21="G"),IF(D21="",0,D21),IF(D21="","",D21-E21)) -> 0
A22: 45794 | B22: Sa | E22: =IF(WEEKDAY(A22,2)<=5,Übersicht!$B$4,0) -> 0 | F22: =IF(OR(C22="U",C22="K",C22="F",C22="G"),IF(D22="",0,D22),IF(D22="","",D22-E22))
A23: 45795 | B23: So | E23: =IF(WEEKDAY(A23,2)<=5,Übersicht!$B$4,0) -> 0 | F23: =IF(OR(C23="U",C23="K",C23="F",C23="G"),IF(D23="",0,D23),IF(D23="","",D23-E23))
A24: 45796 | B24: Mo | C24: SD | D24: 8 | E24: =IF(WEEKDAY(A24,2)<=5,Übersicht!$B$4,0) -> 8 | F24: =IF(OR(C24="U",C24="K",C24="F",C24="G"),IF(D24="",0,D24),IF(D24="","",D24-E24)) -> 0
A25: 45797 | B25: Di | C25: SD | D25: 8 | E25: =IF(WEEKDAY(A25,2)<=5,Übersicht!$B$4,0) -> 8 | F25: =IF(OR(C25="U",C25="K",C25="F",C25="G"),IF(D25="",0,D25),IF(D25="","",D25-E25)) -> 0
A26: 45798 | B26: Mi | C26: SD | D26: 8 | E26: =IF(WEEKDAY(A26,2)<=5,Übersicht!$B$4,0) -> 8 | F26: =IF(OR(C26="U",C26="K",C26="F",C26="G"),IF(D26="",0,D26),IF(D26="","",D26-E26)) -> 0
A27: 45799 | B27: Do | C27: SD | D27: 8 | E27: =IF(WEEKDAY(A27,2)<=5,Übersicht!$B$4,0) -> 8 | F27: =IF(OR(C27="U",C27="K",C27="F",C27="G"),IF(D27="",0,D27),IF(D27="","",D27-E27)) -> 0
A28: 45800 | B28: Fr | C28: SD | D28: 8 | E28: =IF(WEEKDAY(A28,2)<=5,Übersicht!$B$4,0) -> 8 | F28: =IF(OR(C28="U",C28="K",C28="F",C28="G"),IF(D28="",0,D28),IF(D28="","",D28-E28)) -> 0
A29: 45801 | B29: Sa | E29: =IF(WEEKDAY(A29,2)<=5,Übersicht!$B$4,0) -> 0 | F29: =IF(OR(C29="U",C29="K",C29="F",C29="G"),IF(D29="",0,D29),IF(D29="","",D29-E29))
A30: 45802 | B30: So | E30: =IF(WEEKDAY(A30,2)<=5,Übersicht!$B$4,0) -> 0 | F30: =IF(OR(C30="U",C30="K",C30="F",C30="G"),IF(D30="",0,D30),IF(D30="","",D30-E30))
A31: 45803 | B31: Mo | C31: SD | D31: 8 | E31: =IF(WEEKDAY(A31,2)<=5,Übersicht!$B$4,0) -> 8 | F31: =IF(OR(C31="U",C31="K",C31="F",C31="G"),IF(D31="",0,D31),IF(D31="","",D31-E31)) -> 0
A32: 45804 | B32: Di | C32: SD | D32: 8 | E32: =IF(WEEKDAY(A32,2)<=5,Übersicht!$B$4,0) -> 8 | F32: =IF(OR(C32="U",C32="K",C32="F",C32="G"),IF(D32="",0,D32),IF(D32="","",D32-E32)) -> 0
A33: 45805 | B33: Mi | C33: SD | D33: 8 | E33: =IF(WEEKDAY(A33,2)<=5,Übersicht!$B$4,0) -> 8 | F33: =IF(OR(C33="U",C33="K",C33="F",C33="G"),IF(D33="",0,D33),IF(D33="","",D33-E33)) -> 0
A34: 45806 | B34: Do | C34: F | E34: =IF(WEEKDAY(A34,2)<=5,Übersicht!$B$4,0) -> 8 | F34: =IF(OR(C34="U",C34="K",C34="F",C34="G"),IF(D34="",0,D34),IF(D34="","",D34-E34)) -> 0 | G34: Feiertag BW: Christi Himmelfahrt
A35: 45807 | B35: Fr | C35: U | E35: =IF(WEEKDAY(A35,2)<=5,Übersicht!$B$4,0) -> 8 | F35: =IF(OR(C35="U",C35="K",C35="F",C35="G"),IF(D35="",0,D35),IF(D35="","",D35-E35)) -> 0
A36: 45808 | B36: Sa | E36: =IF(WEEKDAY(A36,2)<=5,Übersicht!$B$4,0) -> 0 | F36: =IF(OR(C36="U",C36="K",C36="F",C36="G"),IF(D36="",0,D36),IF(D36="","",D36-E36))
A38: Summe | D38: =SUM(D6:D36)+SUMIF(C6:C36,"U",E6:E36)+SUMIF(C6:C36,"K",E6:E36)+SUMIF(C6:C36,"F",E6:E36)+SUMIF(C6:C36,"G",E6:E36) -> 176 | E38: =SUM(E6:E36) -> 176 | F38: =SUM(F6:F36) -> 0
A39: Arbeitstage (Soll) | B39: =COUNTIF(E6:E36,">0") -> 22
A40: Urlaubstage | B40: =COUNTIF(C6:C36,"U") -> 2
A41: Krankheitstage | B41: =COUNTIF(C6:C36,"K") -> 0
A42: Saldo kumuliert (Std.) | B42: =Übersicht!F19 -> 0

Sheet Jun 2025
A1: Zeiterfassung Juni 2025
A2: Name: | B2: Simon Blasen
A3: Gelb = Eingabe · Ist-Std. als Dezimalzahl (8,25 = 8 Std. 15 Min.) · Art: U Urlaub, K Krank, F Feiertag, G Gleittag
A5: Datum | B5: Tag | C5: Art | D5: Ist-Std. | E5: Soll-Std. | F5: Differenz | G5: Bemerkung
A6: 45809 | B6: So | E6: =IF(WEEKDAY(A6,2)<=5,Übersicht!$B$4,0) -> 0 | F6: =IF(OR(C6="U",C6="K",C6="F",C6="G"),IF(D6="",0,D6),IF(D6="","",D6-E6))
A7: 45810 | B7: Mo | C7: P | D7: 0 | E7: =IF(WEEKDAY(A7,2)<=5,Übersicht!$B$4,0) -> 8 | F7: =IF(OR(C7="U",C7="K",C7="F",C7="G"),IF(D7="",0,D7),IF(D7="","",D7-E7)) -> -8 | G7: Safety Game
A8: 45811 | B8: Di | C8: P | D8: 0 | E8: =IF(WEEKDAY(A8,2)<=5,Übersicht!$B$4,0) -> 8 | F8: =IF(OR(C8="U",C8="K",C8="F",C8="G"),IF(D8="",0,D8),IF(D8="","",D8-E8)) -> -8 | G8: Safety Game
A9: 45812 | B9: Mi | C9: SD | D9: 8 | E9: =IF(WEEKDAY(A9,2)<=5,Übersicht!$B$4,0) -> 8 | F9: =IF(OR(C9="U",C9="K",C9="F",C9="G"),IF(D9="",0,D9),IF(D9="","",D9-E9)) -> 0
A10: 45813 | B10: Do | C10: SD | D10: 8 | E10: =IF(WEEKDAY(A10,2)<=5,Übersicht!$B$4,0) -> 8 | F10: =IF(OR(C10="U",C10="K",C10="F",C10="G"),IF(D10="",0,D10),IF(D10="","",D10-E10)) -> 0
A11: 45814 | B11: Fr | C11: SD | D11: 8 | E11: =IF(WEEKDAY(A11,2)<=5,Übersicht!$B$4,0) -> 8 | F11: =IF(OR(C11="U",C11="K",C11="F",C11="G"),IF(D11="",0,D11),IF(D11="","",D11-E11)) -> 0
A12: 45815 | B12: Sa | E12: =IF(WEEKDAY(A12,2)<=5,Übersicht!$B$4,0) -> 0 | F12: =IF(OR(C12="U",C12="K",C12="F",C12="G"),IF(D12="",0,D12),IF(D12="","",D12-E12))
A13: 45816 | B13: So | E13: =IF(WEEKDAY(A13,2)<=5,Übersicht!$B$4,0) -> 0 | F13: =IF(OR(C13="U",C13="K",C13="F",C13="G"),IF(D13="",0,D13),IF(D13="","",D13-E13))
A14: 45817 | B14: Mo | C14: F | E14: =IF(WEEKDAY(A14,2)<=5,Übersicht!$B$4,0) -> 8 | F14: =IF(OR(C14="U",C14="K",C14="F",C14="G"),IF(D14="",0,D14),IF(D14="","",D14-E14)) -> 0 | G14: Feiertag BW: Pfingstmontag
A15: 45818 | B15: Di | C15: SD | D15: 8 | E15: =IF(WEEKDAY(A15,2)<=5,Übersicht!$B$4,0) -> 8 | F15: =IF(OR(C15="U",C15="K",C15="F",C15="G"),IF(D15="",0,D15),IF(D15="","",D15-E15)) -> 0
A16: 45819 | B16: Mi | C16: SD | D16: 8 | E16: =IF(WEEKDAY(A16,2)<=5,Übersicht!$B$4,0) -> 8 | F16: =IF(OR(C16="U",C16="K",C16="F",C16="G"),IF(D16="",0,D16),IF(D16="","",D16-E16)) -> 0
A17: 45820 | B17: Do | C17: SD | D17: 8 | E17: =IF(WEEKDAY(A17,2)<=5,Übersicht!$B$4,0) -> 8 | F17: =IF(OR(C17="U",C17="K",C17="F",C17="G"),IF(D17="",0,D17),IF(D17="","",D17-E17)) -> 0
A18: 45821 | B18: Fr | C18: SD | D18: 8 | E18: =IF(WEEKDAY(A18,2)<=5,Übersicht!$B$4,0) -> 8 | F18: =IF(OR(C18="U",C18="K",C18="F",C18="G"),IF(D18="",0,D18),IF(D18="","",D18-E18)) -> 0
A19: 45822 | B19: Sa | E19: =IF(WEEKDAY(A19,2)<=5,Übersicht!$B$4,0) -> 0 | F19: =IF(OR(C19="U",C19="K",C19="F",C19="G"),IF(D19="",0,D19),IF(D19="","",D19-E19))
A20: 45823 | B20: So | E20: =IF(WEEKDAY(A20,2)<=5,Übersicht!$B$4,0) -> 0 | F20: =IF(OR(C20="U",C20="K",C20="F",C20="G"),IF(D20="",0,D20),IF(D20="","",D20-E20))
A21: 45824 | B21: Mo | C21: SD | D21: 8 | E21: =IF(WEEKDAY(A21,2)<=5,Übersicht!$B$4,0) -> 8 | F21: =IF(OR(C21="U",C21="K",C21="F",C21="G"),IF(D21="",0,D21),IF(D21="","",D21-E21)) -> 0
A22: 45825 | B22: Di | C22: SD | D22: 8 | E22: =IF(WEEKDAY(A22,2)<=5,Übersicht!$B$4,0) -> 8 | F22: =IF(OR(C22="U",C22="K",C22="F",C22="G"),IF(D22="",0,D22),IF(D22="","",D22-E22)) -> 0
A23: 45826 | B23: Mi | C23: SD | D23: 8 | E23: =IF(WEEKDAY(A23,2)<=5,Übersicht!$B$4,0) -> 8 | F23: =IF(OR(C23="U",C23="K",C23="F",C23="G"),IF(D23="",0,D23),IF(D23="","",D23-E23)) -> 0
A24: 45827 | B24: Do | C24: F | E24: =IF(WEEKDAY(A24,2)<=5,Übersicht!$B$4,0) -> 8 | F24: =IF(OR(C24="U",C24="K",C24="F",C24="G"),IF(D24="",0,D24),IF(D24="","",D24-E24)) -> 0 | G24: Feiertag BW: Fronleichnam
A25: 45828 | B25: Fr | C25: SD | D25: 8 | E25: =IF(WEEKDAY(A25,2)<=5,Übersicht!$B$4,0) -> 8 | F25: =IF(OR(C25="U",C25="K",C25="F",C25="G"),IF(D25="",0,D25),IF(D25="","",D25-E25)) -> 0
A26: 45829 | B26: Sa | E26: =IF(WEEKDAY(A26,2)<=5,Übersicht!$B$4,0) -> 0 | F26: =IF(OR(C26="U",C26="K",C26="F",C26="G"),IF(D26="",0,D26),IF(D26="","",D26-E26))
A27: 45830 | B27: So | E27: =IF(WEEKDAY(A27,2)<=5,Übersicht!$B$4,0) -> 0 | F27: =IF(OR(C27="U",C27="K",C27="F",C27="G"),IF(D27="",0,D27),IF(D27="","",D27-E27))
A28: 45831 | B28: Mo | C28: SD | D28: 8 | E28: =IF(WEEKDAY(A28,2)<=5,Übersicht!$B$4,0) -> 8 | F28: =IF(OR(C28="U",C28="K",C28="F",C28="G"),IF(D28="",0,D28),IF(D28="","",D28-E28)) -> 0
A29: 45832 | B29: Di | C29: SD | D29: 8 | E29: =IF(WEEKDAY(A29,2)<=5,Übersicht!$B$4,0) -> 8 | F29: =IF(OR(C29="U",C29="K",C29="F",C29="G"),IF(D29="",0,D29),IF(D29="","",D29-E29)) -> 0
A30: 45833 | B30: Mi | C30: SD | D30: 8 | E30: =IF(WEEKDAY(A30,2)<=5,Übersicht!$B$4,0) -> 8 | F30: =IF(OR(C30="U",C30="K",C30="F",C30="G"),IF(D30="",0,D30),IF(D30="","",D30-E30)) -> 0
A31: 45834 | B31: Do | C31: SD | D31: 8 | E31: =IF(WEEKDAY(A31,2)<=5,Übersicht!$B$4,0) -> 8 | F31: =IF(OR(C31="U",C31="K",C31="F",C31="G"),IF(D31="",0,D31),IF(D31="","",D31-E31)) -> 0
A32: 45835 | B32: Fr | C32: SD | D32: 8 | E32: =IF(WEEKDAY(A32,2)<=5,Übersicht!$B$4,0) -> 8 | F32: =IF(OR(C32="U",C32="K",C32="F",C32="G"),IF(D32="",0,D32),IF(D32="","",D32-E32)) -> 0
A33: 45836 | B33: Sa | E33: =IF(WEEKDAY(A33,2)<=5,Übersicht!$B$4,0) -> 0 | F33: =IF(OR(C33="U",C33="K",C33="F",C33="G"),IF(D33="",0,D33),IF(D33="","",D33-E33))
A34: 45837 | B34: So | E34: =IF(WEEKDAY(A34,2)<=5,Übersicht!$B$4,0) -> 0 | F34: =IF(OR(C34="U",C34="K",C34="F",C34="G"),IF(D34="",0,D34),IF(D34="","",D34-E34))
A35: 45838 | B35: Mo | C35: SD | D35: 8 | E35: =IF(WEEKDAY(A35,2)<=5,Übersicht!$B$4,0) -> 8 | F35: =IF(OR(C35="U",C35="K",C35="F",C35="G"),IF(D35="",0,D35),IF(D35="","",D35-E35)) -> 0
A38: Summe | D38: =SUM(D6:D36)+SUMIF(C6:C36,"U",E6:E36)+SUMIF(C6:C36,"K",E6:E36)+SUMIF(C6:C36,"F",E6:E36)+SUMIF(C6:C36,"G",E6:E36) -> 152 | E38: =SUM(E6:E36) -> 168 | F38: =SUM(F6:F36) -> -16
A39: Arbeitstage (Soll) | B39: =COUNTIF(E6:E36,">0") -> 21
A40: Urlaubstage | B40: =COUNTIF(C6:C36,"U") -> 0
A41: Krankheitstage | B41: =COUNTIF(C6:C36,"K") -> 0
A42: Saldo kumuliert (Std.) | B42: =Übersicht!F20 -> -16

Sheet Jul 2025
A1: Zeiterfassung Juli 2025
A2: Name: | B2: Simon Blasen
A3: Gelb = Eingabe · Ist-Std. als Dezimalzahl (8,25 = 8 Std. 15 Min.) · Art: U Urlaub, K Krank, F Feiertag, G Gleittag
A5: Datum | B5: Tag | C5: Art | D5: Ist-Std. | E5: Soll-Std. | F5: Differenz | G5: Bemerkung
A6: 45839 | B6: Di | C6: SD | D6: 8 | E6: =IF(WEEKDAY(A6,2)<=5,Übersicht!$B$4,0) -> 8 | F6: =IF(OR(C6="U",C6="K",C6="F",C6="G"),IF(D6="",0,D6),IF(D6="","",D6-E6)) -> 0
A7: 45840 | B7: Mi | C7: SD | D7: 8 | E7: =IF(WEEKDAY(A7,2)<=5,Übersicht!$B$4,0) -> 8 | F7: =IF(OR(C7="U",C7="K",C7="F",C7="G"),IF(D7="",0,D7),IF(D7="","",D7-E7)) -> 0
A8: 45841 | B8: Do | C8: SD | D8: 8 | E8: =IF(WEEKDAY(A8,2)<=5,Übersicht!$B$4,0) -> 8 | F8: =IF(OR(C8="U",C8="K",C8="F",C8="G"),IF(D8="",0,D8),IF(D8="","",D8-E8)) -> 0
A9: 45842 | B9: Fr | C9: SD | D9: 8 | E9: =IF(WEEKDAY(A9,2)<=5,Übersicht!$B$4,0) -> 8 | F9: =IF(OR(C9="U",C9="K",C9="F",C9="G"),IF(D9="",0,D9),IF(D9="","",D9-E9)) -> 0
A10: 45843 | B10: Sa | E10: =IF(WEEKDAY(A10,2)<=5,Übersicht!$B$4,0) -> 0 | F10: =IF(OR(C10="U",C10="K",C10="F",C10="G"),IF(D10="",0,D10),IF(D10="","",D10-E10))
A11: 45844 | B11: So | E11: =IF(WEEKDAY(A11,2)<=5,Übersicht!$B$4,0) -> 0 | F11: =IF(OR(C11="U",C11="K",C11="F",C11="G"),IF(D11="",0,D11),IF(D11="","",D11-E11))
A12: 45845 | B12: Mo | C12: SD | D12: 8 | E12: =IF(WEEKDAY(A12,2)<=5,Übersicht!$B$4,0) -> 8 | F12: =IF(OR(C12="U",C12="K",C12="F",C12="G"),IF(D12="",0,D12),IF(D12="","",D12-E12)) -> 0
A13: 45846 | B13: Di | C13: SD | D13: 8 | E13: =IF(WEEKDAY(A13,2)<=5,Übersicht!$B$4,0) -> 8 | F13: =IF(OR(C13="U",C13="K",C13="F",C13="G"),IF(D13="",0,D13),IF(D13="","",D13-E13)) -> 0
A14: 45847 | B14: Mi | C14: P | E14: =IF(WEEKDAY(A14,2)<=5,Übersicht!$B$4,0) -> 8 | F14: =IF(OR(C14="U",C14="K",C14="F",C14="G"),IF(D14="",0,D14),IF(D14="","",D14-E14)) | G14: German Dev Days
A15: 45848 | B15: Do | C15: P | E15: =IF(WEEKDAY(A15,2)<=5,Übersicht!$B$4,0) -> 8 | F15: =IF(OR(C15="U",C15="K",C15="F",C15="G"),IF(D15="",0,D15),IF(D15="","",D15-E15)) | G15: German Dev Days
A16: 45849 | B16: Fr | C16: SD | D16: 8 | E16: =IF(WEEKDAY(A16,2)<=5,Übersicht!$B$4,0) -> 8 | F16: =IF(OR(C16="U",C16="K",C16="F",C16="G"),IF(D16="",0,D16),IF(D16="","",D16-E16)) -> 0
A17: 45850 | B17: Sa | E17: =IF(WEEKDAY(A17,2)<=5,Übersicht!$B$4,0) -> 0 | F17: =IF(OR(C17="U",C17="K",C17="F",C17="G"),IF(D17="",0,D17),IF(D17="","",D17-E17))
A18: 45851 | B18: So | E18: =IF(WEEKDAY(A18,2)<=5,Übersicht!$B$4,0) -> 0 | F18: =IF(OR(C18="U",C18="K",C18="F",C18="G"),IF(D18="",0,D18),IF(D18="","",D18-E18))
A19: 45852 | B19: Mo | C19: SD | D19: 8 | E19: =IF(WEEKDAY(A19,2)<=5,Übersicht!$B$4,0) -> 8 | F19: =IF(OR(C19="U",C19="K",C19="F",C19="G"),IF(D19="",0,D19),IF(D19="","",D19-E19)) -> 0
A20: 45853 | B20: Di | C20: SD | D20: 8 | E20: =IF(WEEKDAY(A20,2)<=5,Übersicht!$B$4,0) -> 8 | F20: =IF(OR(C20="U",C20="K",C20="F",C20="G"),IF(D20="",0,D20),IF(D20="","",D20-E20)) -> 0
A21: 45854 | B21: Mi | C21: SD | D21: 8 | E21: =IF(WEEKDAY(A21,2)<=5,Übersicht!$B$4,0) -> 8 | F21: =IF(OR(C21="U",C21="K",C21="F",C21="G"),IF(D21="",0,D21),IF(D21="","",D21-E21)) -> 0
A22: 45855 | B22: Do | C22: SD | D22: 8 | E22: =IF(WEEKDAY(A22,2)<=5,Übersicht!$B$4,0) -> 8 | F22: =IF(OR(C22="U",C22="K",C22="F",C22="G"),IF(D22="",0,D22),IF(D22="","",D22-E22)) -> 0
A23: 45856 | B23: Fr | C23: SD | D23: 8 | E23: =IF(WEEKDAY(A23,2)<=5,Übersicht!$B$4,0) -> 8 | F23: =IF(OR(C23="U",C23="K",C23="F",C23="G"),IF(D23="",0,D23),IF(D23="","",D23-E23)) -> 0
A24: 45857 | B24: Sa | E24: =IF(WEEKDAY(A24,2)<=5,Übersicht!$B$4,0) -> 0 | F24: =IF(OR(C24="U",C24="K",C24="F",C24="G"),IF(D24="",0,D24),IF(D24="","",D24-E24))
A25: 45858 | B25: So | E25: =IF(WEEKDAY(A25,2)<=5,Übersicht!$B$4,0) -> 0 | F25: =IF(OR(C25="U",C25="K",C25="F",C25="G"),IF(D25="",0,D25),IF(D25="","",D25-E25))
A26: 45859 | B26: Mo | C26: SD | D26: 8 | E26: =IF(WEEKDAY(A26,2)<=5,Übersicht!$B$4,0) -> 8 | F26: =IF(OR(C26="U",C26="K",C26="F",C26="G"),IF(D26="",0,D26),IF(D26="","",D26-E26)) -> 0
A27: 45860 | B27: Di | C27: SD | D27: 8 | E27: =IF(WEEKDAY(A27,2)<=5,Übersicht!$B$4,0) -> 8 | F27: =IF(OR(C27="U",C27="K",C27="F",C27="G"),IF(D27="",0,D27),IF(D27="","",D27-E27)) -> 0
A28: 45861 | B28: Mi | C28: SD | D28: 8 | E28: =IF(WEEKDAY(A28,2)<=5,Übersicht!$B$4,0) -> 8 | F28: =IF(OR(C28="U",C28="K",C28="F",C28="G"),IF(D28="",0,D28),IF(D28="","",D28-E28)) -> 0
A29: 45862 | B29: Do | C29: SD | D29: 8 | E29: =IF(WEEKDAY(A29,2)<=5,Übersicht!$B$4,0) -> 8 | F29: =IF(OR(C29="U",C29="K",C29="F",C29="G"),IF(D29="",0,D29),IF(D29="","",D29-E29)) -> 0
A30: 45863 | B30: Fr | C30: SD | D30: 8 | E30: =IF(WEEKDAY(A30,2)<=5,Übersicht!$B$4,0) -> 8 | F30: =IF(OR(C30="U",C30="K",C30="F",C30="G"),IF(D30="",0,D30),IF(D30="","",D30-E30)) -> 0
A31: 45864 | B31: Sa | E31: =IF(WEEKDAY(A31,2)<=5,Übersicht!$B$4,0) -> 0 | F31: =IF(OR(C31="U",C31="K",C31="F",C31="G"),IF(D31="",0,D31),IF(D31="","",D31-E31))
A32: 45865 | B32: So | E32: =IF(WEEKDAY(A32,2)<=5,Übersicht!$B$4,0) -> 0 | F32: =IF(OR(C32="U",C32="K",C32="F",C32="G"),IF(D32="",0,D32),IF(D32="","",D32-E32))
A33: 45866 | B33: Mo | C33: SD | D33: 8 | E33: =IF(WEEKDAY(A33,2)<=5,Übersicht!$B$4,0) -> 8 | F33: =IF(OR(C33="U",C33="K",C33="F",C33="G"),IF(D33="",0,D33),IF(D33="","",D33-E33)) -> 0
A34: 45867 | B34: Di | C34: SD | D34: 8 | E34: =IF(WEEKDAY(A34,2)<=5,Übersicht!$B$4,0) -> 8 | F34: =IF(OR(C34="U",C34="K",C34="F",C34="G"),IF(D34="",0,D34),IF(D34="","",D34-E34)) -> 0
A35: 45868 | B35: Mi | C35: SD | D35: 8 | E35: =IF(WEEKDAY(A35,2)<=5,Übersicht!$B$4,0) -> 8 | F35: =IF(OR(C35="U",C35="K",C35="F",C35="G"),IF(D35="",0,D35),IF(D35="","",D35-E35)) -> 0
A36: 45869 | B36: Do | C36: U | E36: =IF(WEEKDAY(A36,2)<=5,Übersicht!$B$4,0) -> 8 | F36: =IF(OR(C36="U",C36="K",C36="F",C36="G"),IF(D36="",0,D36),IF(D36="","",D36-E36)) -> 0
A38: Summe | D38: =SUM(D6:D36)+SUMIF(C6:C36,"U",E6:E36)+SUMIF(C6:C36,"K",E6:E36)+SUMIF(C6:C36,"F",E6:E36)+SUMIF(C6:C36,"G",E6:E36) -> 168 | E38: =SUM(E6:E36) -> 184 | F38: =SUM(F6:F36) -> 0
A39: Arbeitstage (Soll) | B39: =COUNTIF(E6:E36,">0") -> 23
A40: Urlaubstage | B40: =COUNTIF(C6:C36,"U") -> 1
A41: Krankheitstage | B41: =COUNTIF(C6:C36,"K") -> 0
A42: Saldo kumuliert (Std.) | B42: =Übersicht!F21 -> -16

Sheet Aug 2025
A1: Zeiterfassung August 2025
A2: Name: | B2: Simon Blasen
A3: Gelb = Eingabe · Ist-Std. als Dezimalzahl (8,25 = 8 Std. 15 Min.) · Art: U Urlaub, K Krank, F Feiertag, G Gleittag
A5: Datum | B5: Tag | C5: Art | D5: Ist-Std. | E5: Soll-Std. | F5: Differenz | G5: Bemerkung
A6: 45870 | B6: Fr | C6: U | E6: =IF(WEEKDAY(A6,2)<=5,Übersicht!$B$4,0) -> 8 | F6: =IF(OR(C6="U",C6="K",C6="F",C6="G"),IF(D6="",0,D6),IF(D6="","",D6-E6)) -> 0
A7: 45871 | B7: Sa | E7: =IF(WEEKDAY(A7,2)<=5,Übersicht!$B$4,0) -> 0 | F7: =IF(OR(C7="U",C7="K",C7="F",C7="G"),IF(D7="",0,D7),IF(D7="","",D7-E7))
A8: 45872 | B8: So | E8: =IF(WEEKDAY(A8,2)<=5,Übersicht!$B$4,0) -> 0 | F8: =IF(OR(C8="U",C8="K",C8="F",C8="G"),IF(D8="",0,D8),IF(D8="","",D8-E8))
A9: 45873 | B9: Mo | C9: U | E9: =IF(WEEKDAY(A9,2)<=5,Übersicht!$B$4,0) -> 8 | F9: =IF(OR(C9="U",C9="K",C9="F",C9="G"),IF(D9="",0,D9),IF(D9="","",D9-E9)) -> 0
A10: 45874 | B10: Di | C10: U | E10: =IF(WEEKDAY(A10,2)<=5,Übersicht!$B$4,0) -> 8 | F10: =IF(OR(C10="U",C10="K",C10="F",C10="G"),IF(D10="",0,D10),IF(D10="","",D10-E10)) -> 0
A11: 45875 | B11: Mi | C11: U | E11: =IF(WEEKDAY(A11,2)<=5,Übersicht!$B$4,0) -> 8 | F11: =IF(OR(C11="U",C11="K",C11="F",C11="G"),IF(D11="",0,D11),IF(D11="","",D11-E11)) -> 0
A12: 45876 | B12: Do | C12: U | E12: =IF(WEEKDAY(A12,2)<=5,Übersicht!$B$4,0) -> 8 | F12: =IF(OR(C12="U",C12="K",C12="F",C12="G"),IF(D12="",0,D12),IF(D12="","",D12-E12)) -> 0
A13: 45877 | B13: Fr | C13: U | E13: =IF(WEEKDAY(A13,2)<=5,Übersicht!$B$4,0) -> 8 | F13: =IF(OR(C13="U",C13="K",C13="F",C13="G"),IF(D13="",0,D13),IF(D13="","",D13-E13)) -> 0
A14: 45878 | B14: Sa | E14: =IF(WEEKDAY(A14,2)<=5,Übersicht!$B$4,0) -> 0 | F14: =IF(OR(C14="U",C14="K",C14="F",C14="G"),IF(D14="",0,D14),IF(D14="","",D14-E14))
A15: 45879 | B15: So | E15: =IF(WEEKDAY(A15,2)<=5,Übersicht!$B$4,0) -> 0 | F15: =IF(OR(C15="U",C15="K",C15="F",C15="G"),IF(D15="",0,D15),IF(D15="","",D15-E15))
A16: 45880 | B16: Mo | C16: U | E16: =IF(WEEKDAY(A16,2)<=5,Übersicht!$B$4,0) -> 8 | F16: =IF(OR(C16="U",C16="K",C16="F",C16="G"),IF(D16="",0,D16),IF(D16="","",D16-E16)) -> 0
A17: 45881 | B17: Di | C17: U | E17: =IF(WEEKDAY(A17,2)<=5,Übersicht!$B$4,0) -> 8 | F17: =IF(OR(C17="U",C17="K",C17="F",C17="G"),IF(D17="",0,D17),IF(D17="","",D17-E17)) -> 0
A18: 45882 | B18: Mi | C18: U | E18: =IF(WEEKDAY(A18,2)<=5,Übersicht!$B$4,0) -> 8 | F18: =IF(OR(C18="U",C18="K",C18="F",C18="G"),IF(D18="",0,D18),IF(D18="","",D18-E18)) -> 0
A19: 45883 | B19: Do | C19: SD | D19: 8 | E19: =IF(WEEKDAY(A19,2)<=5,Übersicht!$B$4,0) -> 8 | F19: =IF(OR(C19="U",C19="K",C19="F",C19="G"),IF(D19="",0,D19),IF(D19="","",D19-E19)) -> 0
A20: 45884 | B20: Fr | C20: SD | D20: 8 | E20: =IF(WEEKDAY(A20,2)<=5,Übersicht!$B$4,0) -> 8 | F20: =IF(OR(C20="U",C20="K",C20="F",C20="G"),IF(D20="",0,D20),IF(D20="","",D20-E20)) -> 0
A21: 45885 | B21: Sa | E21: =IF(WEEKDAY(A21,2)<=5,Übersicht!$B$4,0) -> 0 | F21: =IF(OR(C21="U",C21="K",C21="F",C21="G"),IF(D21="",0,D21),IF(D21="","",D21-E21))
A22: 45886 | B22: So | E22: =IF(WEEKDAY(A22,2)<=5,Übersicht!$B$4,0) -> 0 | F22: =IF(OR(C22="U",C22="K",C22="F",C22="G"),IF(D22="",0,D22),IF(D22="","",D22-E22))
A23: 45887 | B23: Mo | C23: SD | D23: 8 | E23: =IF(WEEKDAY(A23,2)<=5,Übersicht!$B$4,0) -> 8 | F23: =IF(OR(C23="U",C23="K",C23="F",C23="G"),IF(D23="",0,D23),IF(D23="","",D23-E23)) -> 0
A24: 45888 | B24: Di | C24: SD | D24: 4 | E24: =IF(WEEKDAY(A24,2)<=5,Übersicht!$B$4,0) -> 8 | F24: =IF(OR(C24="U",C24="K",C24="F",C24="G"),IF(D24="",0,D24),IF(D24="","",D24-E24)) -> -4 | G24: Gamescom
A25: 45889 | B25: Mi | C25: P | E25: =IF(WEEKDAY(A25,2)<=5,Übersicht!$B$4,0) -> 8 | F25: =IF(OR(C25="U",C25="K",C25="F",C25="G"),IF(D25="",0,D25),IF(D25="","",D25-E25)) | G25: Gamescom
A26: 45890 | B26: Do | C26: P | E26: =IF(WEEKDAY(A26,2)<=5,Übersicht!$B$4,0) -> 8 | F26: =IF(OR(C26="U",C26="K",C26="F",C26="G"),IF(D26="",0,D26),IF(D26="","",D26-E26)) | G26: Gamescom
A27: 45891 | B27: Fr | C27: SD | D27: 8 | E27: =IF(WEEKDAY(A27,2)<=5,Übersicht!$B$4,0) -> 8 | F27: =IF(OR(C27="U",C27="K",C27="F",C27="G"),IF(D27="",0,D27),IF(D27="","",D27-E27)) -> 0
A28: 45892 | B28: Sa | E28: =IF(WEEKDAY(A28,2)<=5,Übersicht!$B$4,0) -> 0 | F28: =IF(OR(C28="U",C28="K",C28="F",C28="G"),IF(D28="",0,D28),IF(D28="","",D28-E28))
A29: 45893 | B29: So | E29: =IF(WEEKDAY(A29,2)<=5,Übersicht!$B$4,0) -> 0 | F29: =IF(OR(C29="U",C29="K",C29="F",C29="G"),IF(D29="",0,D29),IF(D29="","",D29-E29))
A30: 45894 | B30: Mo | C30: SD | D30: 8 | E30: =IF(WEEKDAY(A30,2)<=5,Übersicht!$B$4,0) -> 8 | F30: =IF(OR(C30="U",C30="K",C30="F",C30="G"),IF(D30="",0,D30),IF(D30="","",D30-E30)) -> 0
A31: 45895 | B31: Di | C31: SD | D31: 8 | E31: =IF(WEEKDAY(A31,2)<=5,Übersicht!$B$4,0) -> 8 | F31: =IF(OR(C31="U",C31="K",C31="F",C31="G"),IF(D31="",0,D31),IF(D31="","",D31-E31)) -> 0
A32: 45896 | B32: Mi | C32: SD | D32: 8 | E32: =IF(WEEKDAY(A32,2)<=5,Übersicht!$B$4,0) -> 8 | F32: =IF(OR(C32="U",C32="K",C32="F",C32="G"),IF(D32="",0,D32),IF(D32="","",D32-E32)) -> 0
A33: 45897 | B33: Do | C33: SD | D33: 8 | E33: =IF(WEEKDAY(A33,2)<=5,Übersicht!$B$4,0) -> 8 | F33: =IF(OR(C33="U",C33="K",C33="F",C33="G"),IF(D33="",0,D33),IF(D33="","",D33-E33)) -> 0
A34: 45898 | B34: Fr | C34: SD | D34: 8 | E34: =IF(WEEKDAY(A34,2)<=5,Übersicht!$B$4,0) -> 8 | F34: =IF(OR(C34="U",C34="K",C34="F",C34="G"),IF(D34="",0,D34),IF(D34="","",D34-E34)) -> 0
A35: 45899 | B35: Sa | E35: =IF(WEEKDAY(A35,2)<=5,Übersicht!$B$4,0) -> 0 | F35: =IF(OR(C35="U",C35="K",C35="F",C35="G"),IF(D35="",0,D35),IF(D35="","",D35-E35))
A36: 45900 | B36: So | E36: =IF(WEEKDAY(A36,2)<=5,Übersicht!$B$4,0) -> 0 | F36: =IF(OR(C36="U",C36="K",C36="F",C36="G"),IF(D36="",0,D36),IF(D36="","",D36-E36))
A38: Summe | D38: =SUM(D6:D36)+SUMIF(C6:C36,"U",E6:E36)+SUMIF(C6:C36,"K",E6:E36)+SUMIF(C6:C36,"F",E6:E36)+SUMIF(C6:C36,"G",E6:E36) -> 148 | E38: =SUM(E6:E36) -> 168 | F38: =SUM(F6:F36) -> -4
A39: Arbeitstage (Soll) | B39: =COUNTIF(E6:E36,">0") -> 21
A40: Urlaubstage | B40: =COUNTIF(C6:C36,"U") -> 9
A41: Krankheitstage | B41: =COUNTIF(C6:C36,"K") -> 0
A42: Saldo kumuliert (Std.) | B42: =Übersicht!F22 -> -20

Sheet Sep 2025
A1: Zeiterfassung September 2025
A2: Name: | B2: Simon Blasen
A3: Gelb = Eingabe · Ist-Std. als Dezimalzahl (8,25 = 8 Std. 15 Min.) · Art: U Urlaub, K Krank, F Feiertag, G Gleittag
A5: Datum | B5: Tag | C5: Art | D5: Ist-Std. | E5: Soll-Std. | F5: Differenz | G5: Bemerkung
A6: 45901 | B6: Mo | C6: P | E6: =IF(WEEKDAY(A6,2)<=5,Übersicht!$B$4,0) -> 8 | F6: =IF(OR(C6="U",C6="K",C6="F",C6="G"),IF(D6="",0,D6),IF(D6="","",D6-E6)) | G6: Auftragsarbeit
A7: 45902 | B7: Di | C7: SD | D7: 2 | E7: =IF(WEEKDAY(A7,2)<=5,Übersicht!$B$4,0) -> 8 | F7: =IF(OR(C7="U",C7="K",C7="F",C7="G"),IF(D7="",0,D7),IF(D7="","",D7-E7)) -> -6
A8: 45903 | B8: Mi | C8: P | E8: =IF(WEEKDAY(A8,2)<=5,Übersicht!$B$4,0) -> 8 | F8: =IF(OR(C8="U",C8="K",C8="F",C8="G"),IF(D8="",0,D8),IF(D8="","",D8-E8)) | G8: Auftragsarbeit
A9: 45904 | B9: Do | C9: SD | D9: 6 | E9: =IF(WEEKDAY(A9,2)<=5,Übersicht!$B$4,0) -> 8 | F9: =IF(OR(C9="U",C9="K",C9="F",C9="G"),IF(D9="",0,D9),IF(D9="","",D9-E9)) -> -2
A10: 45905 | B10: Fr | C10: P | E10: =IF(WEEKDAY(A10,2)<=5,Übersicht!$B$4,0) -> 8 | F10: =IF(OR(C10="U",C10="K",C10="F",C10="G"),IF(D10="",0,D10),IF(D10="","",D10-E10)) | G10: Auftragsarbeit
A11: 45906 | B11: Sa | E11: =IF(WEEKDAY(A11,2)<=5,Übersicht!$B$4,0) -> 0 | F11: =IF(OR(C11="U",C11="K",C11="F",C11="G"),IF(D11="",0,D11),IF(D11="","",D11-E11))
A12: 45907 | B12: So | E12: =IF(WEEKDAY(A12,2)<=5,Übersicht!$B$4,0) -> 0 | F12: =IF(OR(C12="U",C12="K",C12="F",C12="G"),IF(D12="",0,D12),IF(D12="","",D12-E12))
A13: 45908 | B13: Mo | C13: SD | D13: 8 | E13: =IF(WEEKDAY(A13,2)<=5,Übersicht!$B$4,0) -> 8 | F13: =IF(OR(C13="U",C13="K",C13="F",C13="G"),IF(D13="",0,D13),IF(D13="","",D13-E13)) -> 0
A14: 45909 | B14: Di | C14: SD | D14: 8 | E14: =IF(WEEKDAY(A14,2)<=5,Übersicht!$B$4,0) -> 8 | F14: =IF(OR(C14="U",C14="K",C14="F",C14="G"),IF(D14="",0,D14),IF(D14="","",D14-E14)) -> 0
A15: 45910 | B15: Mi | C15: SD | D15: 8 | E15: =IF(WEEKDAY(A15,2)<=5,Übersicht!$B$4,0) -> 8 | F15: =IF(OR(C15="U",C15="K",C15="F",C15="G"),IF(D15="",0,D15),IF(D15="","",D15-E15)) -> 0
A16: 45911 | B16: Do | C16: SD | D16: 3 | E16: =IF(WEEKDAY(A16,2)<=5,Übersicht!$B$4,0) -> 8 | F16: =IF(OR(C16="U",C16="K",C16="F",C16="G"),IF(D16="",0,D16),IF(D16="","",D16-E16)) -> -5
A17: 45912 | B17: Fr | C17: SD | D17: 6 | E17: =IF(WEEKDAY(A17,2)<=5,Übersicht!$B$4,0) -> 8 | F17: =IF(OR(C17="U",C17="K",C17="F",C17="G"),IF(D17="",0,D17),IF(D17="","",D17-E17)) -> -2
A18: 45913 | B18: Sa | E18: =IF(WEEKDAY(A18,2)<=5,Übersicht!$B$4,0) -> 0 | F18: =IF(OR(C18="U",C18="K",C18="F",C18="G"),IF(D18="",0,D18),IF(D18="","",D18-E18))
A19: 45914 | B19: So | E19: =IF(WEEKDAY(A19,2)<=5,Übersicht!$B$4,0) -> 0 | F19: =IF(OR(C19="U",C19="K",C19="F",C19="G"),IF(D19="",0,D19),IF(D19="","",D19-E19))
A20: 45915 | B20: Mo | C20: P | E20: =IF(WEEKDAY(A20,2)<=5,Übersicht!$B$4,0) -> 8 | F20: =IF(OR(C20="U",C20="K",C20="F",C20="G"),IF(D20="",0,D20),IF(D20="","",D20-E20)) | G20: Auftragsarbeit
A21: 45916 | B21: Di | C21: SD | D21: 8 | E21: =IF(WEEKDAY(A21,2)<=5,Übersicht!$B$4,0) -> 8 | F21: =IF(OR(C21="U",C21="K",C21="F",C21="G"),IF(D21="",0,D21),IF(D21="","",D21-E21)) -> 0
A22: 45917 | B22: Mi | C22: SD | D22: 8 | E22: =IF(WEEKDAY(A22,2)<=5,Übersicht!$B$4,0) -> 8 | F22: =IF(OR(C22="U",C22="K",C22="F",C22="G"),IF(D22="",0,D22),IF(D22="","",D22-E22)) -> 0
A23: 45918 | B23: Do | C23: P | E23: =IF(WEEKDAY(A23,2)<=5,Übersicht!$B$4,0) -> 8 | F23: =IF(OR(C23="U",C23="K",C23="F",C23="G"),IF(D23="",0,D23),IF(D23="","",D23-E23)) | G23: Auftragsarbeit
A24: 45919 | B24: Fr | C24: P | E24: =IF(WEEKDAY(A24,2)<=5,Übersicht!$B$4,0) -> 8 | F24: =IF(OR(C24="U",C24="K",C24="F",C24="G"),IF(D24="",0,D24),IF(D24="","",D24-E24)) | G24: Auftragsarbeit
A25: 45920 | B25: Sa | E25: =IF(WEEKDAY(A25,2)<=5,Übersicht!$B$4,0) -> 0 | F25: =IF(OR(C25="U",C25="K",C25="F",C25="G"),IF(D25="",0,D25),IF(D25="","",D25-E25))
A26: 45921 | B26: So | E26: =IF(WEEKDAY(A26,2)<=5,Übersicht!$B$4,0) -> 0 | F26: =IF(OR(C26="U",C26="K",C26="F",C26="G"),IF(D26="",0,D26),IF(D26="","",D26-E26))
A27: 45922 | B27: Mo | C27: P | E27: =IF(WEEKDAY(A27,2)<=5,Übersicht!$B$4,0) -> 8 | F27: =IF(OR(C27="U",C27="K",C27="F",C27="G"),IF(D27="",0,D27),IF(D27="","",D27-E27)) | G27: Auftragsarbeit
A28: 45923 | B28: Di | C28: SD | D28: 6 | E28: =IF(WEEKDAY(A28,2)<=5,Übersicht!$B$4,0) -> 8 | F28: =IF(OR(C28="U",C28="K",C28="F",C28="G"),IF(D28="",0,D28),IF(D28="","",D28-E28)) -> -2
A29: 45924 | B29: Mi | C29: P | E29: =IF(WEEKDAY(A29,2)<=5,Übersicht!$B$4,0) -> 8 | F29: =IF(OR(C29="U",C29="K",C29="F",C29="G"),IF(D29="",0,D29),IF(D29="","",D29-E29)) | G29: Auftragsarbeit
A30: 45925 | B30: Do | C30: P | E30: =IF(WEEKDAY(A30,2)<=5,Übersicht!$B$4,0) -> 8 | F30: =IF(OR(C30="U",C30="K",C30="F",C30="G"),IF(D30="",0,D30),IF(D30="","",D30-E30)) | G30: Auftragsarbeit
A31: 45926 | B31: Fr | C31: P | E31: =IF(WEEKDAY(A31,2)<=5,Übersicht!$B$4,0) -> 8 | F31: =IF(OR(C31="U",C31="K",C31="F",C31="G"),IF(D31="",0,D31),IF(D31="","",D31-E31)) | G31: Auftragsarbeit
A32: 45927 | B32: Sa | E32: =IF(WEEKDAY(A32,2)<=5,Übersicht!$B$4,0) -> 0 | F32: =IF(OR(C32="U",C32="K",C32="F",C32="G"),IF(D32="",0,D32),IF(D32="","",D32-E32))
A33: 45928 | B33: So | E33: =IF(WEEKDAY(A33,2)<=5,Übersicht!$B$4,0) -> 0 | F33: =IF(OR(C33="U",C33="K",C33="F",C33="G"),IF(D33="",0,D33),IF(D33="","",D33-E33))
A34: 45929 | B34: Mo | C34: P | E34: =IF(WEEKDAY(A34,2)<=5,Übersicht!$B$4,0) -> 8 | F34: =IF(OR(C34="U",C34="K",C34="F",C34="G"),IF(D34="",0,D34),IF(D34="","",D34-E34)) | G34: Auftragsarbeit
A35: 45930 | B35: Di | C35: SD | D35: 8 | E35: =IF(WEEKDAY(A35,2)<=5,Übersicht!$B$4,0) -> 8 | F35: =IF(OR(C35="U",C35="K",C35="F",C35="G"),IF(D35="",0,D35),IF(D35="","",D35-E35)) -> 0
A38: Summe | D38: =SUM(D6:D36)+SUMIF(C6:C36,"U",E6:E36)+SUMIF(C6:C36,"K",E6:E36)+SUMIF(C6:C36,"F",E6:E36)+SUMIF(C6:C36,"G",E6:E36) -> 71 | E38: =SUM(E6:E36) -> 176 | F38: =SUM(F6:F36) -> -17
A39: Arbeitstage (Soll) | B39: =COUNTIF(E6:E36,">0") -> 22
A40: Urlaubstage | B40: =COUNTIF(C6:C36,"U") -> 0
A41: Krankheitstage | B41: =COUNTIF(C6:C36,"K") -> 0
A42: Saldo kumuliert (Std.) | B42: =Übersicht!F23 -> -37

Sheet Okt 2025
A1: Zeiterfassung Oktober 2025
A2: Name: | B2: Simon Blasen
A3: Gelb = Eingabe · Ist-Std. als Dezimalzahl (8,25 = 8 Std. 15 Min.) · Art: U Urlaub, K Krank, F Feiertag, G Gleittag
A5: Datum | B5: Tag | C5: Art | D5: Ist-Std. | E5: Soll-Std. | F5: Differenz | G5: Bemerkung
A6: 45931 | B6: Mi | C6: P | E6: =IF(WEEKDAY(A6,2)<=5,Übersicht!$B$4,0) -> 8 | F6: =IF(OR(C6="U",C6="K",C6="F",C6="G"),IF(D6="",0,D6),IF(D6="","",D6-E6)) | G6: Auftragsarbeit
A7: 45932 | B7: Do | C7: P | E7: =IF(WEEKDAY(A7,2)<=5,Übersicht!$B$4,0) -> 8 | F7: =IF(OR(C7="U",C7="K",C7="F",C7="G"),IF(D7="",0,D7),IF(D7="","",D7-E7)) | G7: Auftragsarbeit
A8: 45933 | B8: Fr | C8: F | E8: =IF(WEEKDAY(A8,2)<=5,Übersicht!$B$4,0) -> 8 | F8: =IF(OR(C8="U",C8="K",C8="F",C8="G"),IF(D8="",0,D8),IF(D8="","",D8-E8)) -> 0 | G8: Feiertag BW: Tag der Deutschen Einheit
A9: 45934 | B9: Sa | E9: =IF(WEEKDAY(A9,2)<=5,Übersicht!$B$4,0) -> 0 | F9: =IF(OR(C9="U",C9="K",C9="F",C9="G"),IF(D9="",0,D9),IF(D9="","",D9-E9))
A10: 45935 | B10: So | E10: =IF(WEEKDAY(A10,2)<=5,Übersicht!$B$4,0) -> 0 | F10: =IF(OR(C10="U",C10="K",C10="F",C10="G"),IF(D10="",0,D10),IF(D10="","",D10-E10))
A11: 45936 | B11: Mo | C11: P | E11: =IF(WEEKDAY(A11,2)<=5,Übersicht!$B$4,0) -> 8 | F11: =IF(OR(C11="U",C11="K",C11="F",C11="G"),IF(D11="",0,D11),IF(D11="","",D11-E11)) | G11: Auftragsarbeit
A12: 45937 | B12: Di | C12: P | E12: =IF(WEEKDAY(A12,2)<=5,Übersicht!$B$4,0) -> 8 | F12: =IF(OR(C12="U",C12="K",C12="F",C12="G"),IF(D12="",0,D12),IF(D12="","",D12-E12)) | G12: Auftragsarbeit
A13: 45938 | B13: Mi | C13: P | E13: =IF(WEEKDAY(A13,2)<=5,Übersicht!$B$4,0) -> 8 | F13: =IF(OR(C13="U",C13="K",C13="F",C13="G"),IF(D13="",0,D13),IF(D13="","",D13-E13)) | G13: Auftragsarbeit
A14: 45939 | B14: Do | C14: SD | D14: 8 | E14: =IF(WEEKDAY(A14,2)<=5,Übersicht!$B$4,0) -> 8 | F14: =IF(OR(C14="U",C14="K",C14="F",C14="G"),IF(D14="",0,D14),IF(D14="","",D14-E14)) -> 0
A15: 45940 | B15: Fr | C15: SD | D15: 6 | E15: =IF(WEEKDAY(A15,2)<=5,Übersicht!$B$4,0) -> 8 | F15: =IF(OR(C15="U",C15="K",C15="F",C15="G"),IF(D15="",0,D15),IF(D15="","",D15-E15)) -> -2
A16: 45941 | B16: Sa | E16: =IF(WEEKDAY(A16,2)<=5,Übersicht!$B$4,0) -> 0 | F16: =IF(OR(C16="U",C16="K",C16="F",C16="G"),IF(D16="",0,D16),IF(D16="","",D16-E16))
A17: 45942 | B17: So | E17: =IF(WEEKDAY(A17,2)<=5,Übersicht!$B$4,0) -> 0 | F17: =IF(OR(C17="U",C17="K",C17="F",C17="G"),IF(D17="",0,D17),IF(D17="","",D17-E17))
A18: 45943 | B18: Mo | C18: P | E18: =IF(WEEKDAY(A18,2)<=5,Übersicht!$B$4,0) -> 8 | F18: =IF(OR(C18="U",C18="K",C18="F",C18="G"),IF(D18="",0,D18),IF(D18="","",D18-E18)) | G18: Auftragsarbeit
A19: 45944 | B19: Di | C19: SD | D19: 8 | E19: =IF(WEEKDAY(A19,2)<=5,Übersicht!$B$4,0) -> 8 | F19: =IF(OR(C19="U",C19="K",C19="F",C19="G"),IF(D19="",0,D19),IF(D19="","",D19-E19)) -> 0
A20: 45945 | B20: Mi | C20: SD | D20: 4 | E20: =IF(WEEKDAY(A20,2)<=5,Übersicht!$B$4,0) -> 8 | F20: =IF(OR(C20="U",C20="K",C20="F",C20="G"),IF(D20="",0,D20),IF(D20="","",D20-E20)) -> -4
A21: 45946 | B21: Do | C21: P | E21: =IF(WEEKDAY(A21,2)<=5,Übersicht!$B$4,0) -> 8 | F21: =IF(OR(C21="U",C21="K",C21="F",C21="G"),IF(D21="",0,D21),IF(D21="","",D21-E21)) | G21: Auftragsarbeit
A22: 45947 | B22: Fr | C22: P | E22: =IF(WEEKDAY(A22,2)<=5,Übersicht!$B$4,0) -> 8 | F22: =IF(OR(C22="U",C22="K",C22="F",C22="G"),IF(D22="",0,D22),IF(D22="","",D22-E22)) | G22: Auftragsarbeit
A23: 45948 | B23: Sa | E23: =IF(WEEKDAY(A23,2)<=5,Übersicht!$B$4,0) -> 0 | F23: =IF(OR(C23="U",C23="K",C23="F",C23="G"),IF(D23="",0,D23),IF(D23="","",D23-E23))
A24: 45949 | B24: So | E24: =IF(WEEKDAY(A24,2)<=5,Übersicht!$B$4,0) -> 0 | F24: =IF(OR(C24="U",C24="K",C24="F",C24="G"),IF(D24="",0,D24),IF(D24="","",D24-E24))
A25: 45950 | B25: Mo | C25: P | E25: =IF(WEEKDAY(A25,2)<=5,Übersicht!$B$4,0) -> 8 | F25: =IF(OR(C25="U",C25="K",C25="F",C25="G"),IF(D25="",0,D25),IF(D25="","",D25-E25)) | G25: Auftragsarbeit
A26: 45951 | B26: Di | C26: P | E26: =IF(WEEKDAY(A26,2)<=5,Übersicht!$B$4,0) -> 8 | F26: =IF(OR(C26="U",C26="K",C26="F",C26="G"),IF(D26="",0,D26),IF(D26="","",D26-E26)) | G26: Auftragsarbeit
A27: 45952 | B27: Mi | C27: P | E27: =IF(WEEKDAY(A27,2)<=5,Übersicht!$B$4,0) -> 8 | F27: =IF(OR(C27="U",C27="K",C27="F",C27="G"),IF(D27="",0,D27),IF(D27="","",D27-E27)) | G27: Auftragsarbeit
A28: 45953 | B28: Do | C28: P | E28: =IF(WEEKDAY(A28,2)<=5,Übersicht!$B$4,0) -> 8 | F28: =IF(OR(C28="U",C28="K",C28="F",C28="G"),IF(D28="",0,D28),IF(D28="","",D28-E28)) | G28: Auftragsarbeit
A29: 45954 | B29: Fr | C29: P | E29: =IF(WEEKDAY(A29,2)<=5,Übersicht!$B$4,0) -> 8 | F29: =IF(OR(C29="U",C29="K",C29="F",C29="G"),IF(D29="",0,D29),IF(D29="","",D29-E29)) | G29: Auftragsarbeit
A30: 45955 | B30: Sa | E30: =IF(WEEKDAY(A30,2)<=5,Übersicht!$B$4,0) -> 0 | F30: =IF(OR(C30="U",C30="K",C30="F",C30="G"),IF(D30="",0,D30),IF(D30="","",D30-E30))
A31: 45956 | B31: So | E31: =IF(WEEKDAY(A31,2)<=5,Übersicht!$B$4,0) -> 0 | F31: =IF(OR(C31="U",C31="K",C31="F",C31="G"),IF(D31="",0,D31),IF(D31="","",D31-E31))
A32: 45957 | B32: Mo | C32: SD | D32: 8 | E32: =IF(WEEKDAY(A32,2)<=5,Übersicht!$B$4,0) -> 8 | F32: =IF(OR(C32="U",C32="K",C32="F",C32="G"),IF(D32="",0,D32),IF(D32="","",D32-E32)) -> 0
A33: 45958 | B33: Di | C33: SD | D33: 8 | E33: =IF(WEEKDAY(A33,2)<=5,Übersicht!$B$4,0) -> 8 | F33: =IF(OR(C33="U",C33="K",C33="F",C33="G"),IF(D33="",0,D33),IF(D33="","",D33-E33)) -> 0
A34: 45959 | B34: Mi | C34: P | E34: =IF(WEEKDAY(A34,2)<=5,Übersicht!$B$4,0) -> 8 | F34: =IF(OR(C34="U",C34="K",C34="F",C34="G"),IF(D34="",0,D34),IF(D34="","",D34-E34)) | G34: Auftragsarbeit
A35: 45960 | B35: Do | C35: SD | D35: 8 | E35: =IF(WEEKDAY(A35,2)<=5,Übersicht!$B$4,0) -> 8 | F35: =IF(OR(C35="U",C35="K",C35="F",C35="G"),IF(D35="",0,D35),IF(D35="","",D35-E35)) -> 0
A36: 45961 | B36: Fr | C36: SD | D36: 8 | E36: =IF(WEEKDAY(A36,2)<=5,Übersicht!$B$4,0) -> 8 | F36: =IF(OR(C36="U",C36="K",C36="F",C36="G"),IF(D36="",0,D36),IF(D36="","",D36-E36)) -> 0
A38: Summe | D38: =SUM(D6:D36)+SUMIF(C6:C36,"U",E6:E36)+SUMIF(C6:C36,"K",E6:E36)+SUMIF(C6:C36,"F",E6:E36)+SUMIF(C6:C36,"G",E6:E36) -> 66 | E38: =SUM(E6:E36) -> 184 | F38: =SUM(F6:F36) -> -6
A39: Arbeitstage (Soll) | B39: =COUNTIF(E6:E36,">0") -> 23
A40: Urlaubstage | B40: =COUNTIF(C6:C36,"U") -> 0
A41: Krankheitstage | B41: =COUNTIF(C6:C36,"K") -> 0
A42: Saldo kumuliert (Std.) | B42: =Übersicht!F24 -> -43

Sheet Nov 2025
A1: Zeiterfassung November 2025
A2: Name: | B2: Simon Blasen
A3: Gelb = Eingabe · Ist-Std. als Dezimalzahl (8,25 = 8 Std. 15 Min.) · Art: U Urlaub, K Krank, F Feiertag, G Gleittag
A5: Datum | B5: Tag | C5: Art | D5: Ist-Std. | E5: Soll-Std. | F5: Differenz | G5: Bemerkung
